<?xml version="1.0" ?>
<!-- =================================================================================== -->
<!-- |    This document was autogenerated by xacro from /home/rpp/rpp_ws/src/robot/mr1000_dual_fr3_description/urdf/robot.urdf.xacro | -->
<!-- |    EDITING THIS FILE BY HAND IS NOT RECOMMENDED                                 | -->
<!-- =================================================================================== -->
<robot name="robot">
    <material name="aluminum">
        <color rgba="0.5 0.5 0.5 1" />
    </material>
    <material name="plastic">
        <color rgba="0.1 0.1 0.1 1" />
    </material>
    <link name="base_link">
        <inertial>
            <origin rpy="0 0 0" xyz="0.00535751635735848 -0.00475269926750788 0.286289355349785" />
            <mass value="73.3229049522862" />
            <inertia ixx="1.12507968751992" ixy="-0.00353362302473179" ixz="-0.00068687827386116" iyy="1.32736920331961" iyz="0.00179315512394436" izz="1.81443755191728" />
        </inertial>
        <visual>
            <origin rpy="0 0 0" xyz="0 0 0" />
            <geometry>
                <mesh filename="package://mr1000_dual_fr3_description/meshes/base_link.STL" />
            </geometry>
            <material name="">
                <color rgba="0.752941176470588 0.752941176470588 0.752941176470588 1" />
            </material>
        </visual>
        <collision>
            <origin rpy="0 0 0" xyz="0 0 0" />
            <geometry>
                <mesh filename="package://mr1000_dual_fr3_description/meshes/base_link.STL" />
            </geometry>
        </collision>
    </link>
    <link name="wheel_LF_LINK">
        <inertial>
            <origin rpy="0 0 0" xyz="7.33709257794146E-08 5.99538122036947E-07 9.76971648636304E-07" />
            <mass value="0.128480801908051" />
            <inertia ixx="3.93723310092569E-05" ixy="1.82829550046287E-10" ixz="-4.54218190438554E-06" iyy="3.67038112753435E-05" iyz="-1.99652333911727E-10" izz="5.19399980479376E-05" />
        </inertial>
        <visual>
            <origin rpy="0 0 0" xyz="0 0 0" />
            <geometry>
                <mesh filename="package://mr1000_dual_fr3_description/meshes/wheel_LF_link.STL" />
            </geometry>
            <material name="">
                <color rgba="1 0.945098039215686 0.905882352941176 1" />
            </material>
        </visual>
        <collision>
            <origin rpy="0 0 0" xyz="0 0 0" />
            <geometry>
                <mesh filename="package://mr1000_dual_fr3_description/meshes/wheel_LF_link.STL" />
            </geometry>
        </collision>
    </link>
    <joint name="wheel_LF_joint" type="continuous">
        <origin rpy="0 0 0" xyz="0.212 0.323100000000001 0" />
        <parent link="base_link" />
        <child link="wheel_LF_LINK" />
        <axis xyz="0 1 0" />
    </joint>
    <link name="wheel_LB_link">
        <inertial>
            <origin rpy="0 0 0" xyz="7.33709257239035E-08 5.9953812314717E-07 9.76971650912262E-07" />
            <mass value="0.128480801908052" />
            <inertia ixx="3.93723310092559E-05" ixy="1.82829524483969E-10" ixz="-4.5421819043867E-06" iyy="3.67038112753418E-05" iyz="-1.9965234198184E-10" izz="5.19399980479348E-05" />
        </inertial>
        <visual>
            <origin rpy="0 0 0" xyz="0 0 0" />
            <geometry>
                <mesh filename="package://mr1000_dual_fr3_description/meshes/wheel_LF_link.STL" />
            </geometry>
            <material name="">
                <color rgba="1 0.945098039215686 0.905882352941176 1" />
            </material>
        </visual>
        <collision>
            <origin rpy="0 0 0" xyz="0 0 0" />
            <geometry>
                <mesh filename="package://mr1000_dual_fr3_description/meshes/wheel_LF_link.STL" />
            </geometry>
        </collision>
    </link>
    <joint name="wheel_LB_joint" type="continuous">
        <origin rpy="0 0 0" xyz="-0.212 0.323099999999999 0" />
        <parent link="base_link" />
        <child link="wheel_LB_link" />
        <axis xyz="0 1 0" />
    </joint>
    <link name="wheel_RF_link">
        <inertial>
            <origin rpy="0 0 0" xyz="-1.72597195591262E-07 -4.21214580992313E-07 9.67357931536128E-07" />
            <mass value="0.128480070881773" />
            <inertia ixx="3.85807198293486E-05" ixy="6.77499260642112E-10" ixz="3.17154606250481E-06" iyy="3.67031869876415E-05" iyz="5.28586976932803E-11" izz="5.27305600806975E-05" />
        </inertial>
        <visual>
            <origin rpy="0 0 0" xyz="0 0 0" />
            <geometry>
                <mesh filename="package://mr1000_dual_fr3_description/meshes/wheel_LF_link.STL" />
            </geometry>
            <material name="">
                <color rgba="1 0.945098039215686 0.905882352941176 1" />
            </material>
        </visual>
        <collision>
            <origin rpy="0 0 0" xyz="0 0 0" />
            <geometry>
                <mesh filename="package://mr1000_dual_fr3_description/meshes/wheel_LF_link.STL" />
            </geometry>
        </collision>
    </link>
    <joint name="wheel_RF_joint" type="continuous">
        <origin rpy="0 0 0" xyz="0.212000000000003 -0.3231 0" />
        <parent link="base_link" />
        <child link="wheel_RF_link" />
        <axis xyz="0 -1 0" />
    </joint>
    <link name="wheel_RB_link">
        <inertial>
            <origin rpy="0 0 0" xyz="-1.72597195535751E-07 -4.21214583379292E-07 9.6735793114755E-07" />
            <mass value="0.128480070881772" />
            <inertia ixx="3.8580719829285E-05" ixy="6.77499249851347E-10" ixz="3.17154606250912E-06" iyy="3.67031869875755E-05" iyz="5.28587034496553E-11" izz="5.27305600806512E-05" />
        </inertial>
        <visual>
            <origin rpy="0 0 0" xyz="0 0 0" />
            <geometry>
                <mesh filename="package://mr1000_dual_fr3_description/meshes/wheel_LF_link.STL" />
            </geometry>
            <material name="">
                <color rgba="1 0.945098039215686 0.905882352941176 1" />
            </material>
        </visual>
        <collision>
            <origin rpy="0 0 0" xyz="0 0 0" />
            <geometry>
                <mesh filename="package://mr1000_dual_fr3_description/meshes/wheel_LF_link.STL" />
            </geometry>
        </collision>
    </link>
    <joint name="wheel_RB_joint" type="continuous">
        <origin rpy="0 0 0" xyz="-0.211999999999997 -0.323100000000002 0" />
        <parent link="base_link" />
        <child link="wheel_RB_link" />
        <axis xyz="0 -1 0" />
    </joint>
    <link name="lidar_F_link">
        <inertial>
            <origin rpy="0 0 0" xyz="0.00130047182335188 8.71661430903336E-05 0.0397106473732433" />
            <mass value="0.101936733121447" />
            <inertia ixx="0.000117105373758523" ixy="1.11586540226324E-07" ixz="-3.34607877093784E-07" iyy="0.000115891247098562" iyz="2.66539587437291E-08" izz="0.000195379409514532" />
        </inertial>
        <visual>
            <origin rpy="0 0 0" xyz="0 0 0" />
            <geometry>
                <mesh filename="package://mr1000_dual_fr3_description/meshes/mid360.STL" />
            </geometry>
            <material name="">
                <color rgba="0.792156862745098 0.819607843137255 0.933333333333333 1" />
            </material>
        </visual>
        <collision>
            <origin rpy="0 0 0" xyz="0 0 0" />
            <geometry>
                <mesh filename="package://mr1000_dual_fr3_description/meshes/mid360.STL" />
            </geometry>
        </collision>
    </link>
    <joint name="lidar_F_joint" type="fixed">
        <origin rpy="0 0 0" xyz="0.3315 -0.301617184983994 0.305999999999299" />
        <parent link="base_link" />
        <child link="lidar_F_link" />
        <axis xyz="0 0 0" />
    </joint>
    <link name="livox_F_frame" />
    <joint name="imu_F_joint" type="fixed">
        <origin rpy="0 0 0" xyz="0.011 0.02329 -0.04412" />
        <parent link="lidar_F_link" />
        <child link="livox_F_frame" />
        <axis xyz="0 0 0" />
    </joint>
    <link name="lidar_B_link">
        <inertial>
            <origin rpy="0 0 0" xyz="0.00130047182335188 8.71661430903336E-05 0.0397106473732433" />
            <mass value="0.101936733121447" />
            <inertia ixx="0.000117105373758523" ixy="1.11586540226324E-07" ixz="-3.34607877093784E-07" iyy="0.000115891247098562" iyz="2.66539587437291E-08" izz="0.000195379409514532" />
        </inertial>
        <visual>
            <origin rpy="0 0 0" xyz="0 0 0" />
            <geometry>
                <mesh filename="package://mr1000_dual_fr3_description/meshes/mid360.STL" />
            </geometry>
            <material name="">
                <color rgba="0.792156862745098 0.819607843137255 0.933333333333333 1" />
            </material>
        </visual>
        <collision>
            <origin rpy="0 0 0" xyz="0 0 0" />
            <geometry>
                <mesh filename="package://mr1000_dual_fr3_description/meshes/mid360.STL" />
            </geometry>
        </collision>
    </link>
    <joint name="lidar_B_joint" type="fixed">
        <origin rpy="0 0 3.14159265358979" xyz="-0.331499999999998 0.29738281501601 0.305999999999299" />
        <parent link="base_link" />
        <child link="lidar_B_link" />
        <axis xyz="0 0 0" />
    </joint>
    <link name="livox_B_frame" />
    <joint name="imu_B_joint" type="fixed">
        <origin rpy="0 0 0" xyz="0.011 0.02329 -0.04412" />
        <parent link="lidar_B_link" />
        <child link="livox_B_frame" />
        <axis xyz="0 0 0" />
    </joint>
    <!-- left -->
    <!-- 手动创建franka连接parent的joint，防止franka的urdf自动创建parent link -->
    <joint name="left_fr3_base_link_joint" type="fixed">
        <parent link="base_link" />
        <child link="left_fr3_link0" />
        <origin rpy="-1.5707963267949 -1.5707963267949 0" xyz="0.153 0.060000000000003 0.968500000000001" />
    </joint>
    <!-- sub-link defining detailed meshes for collision with environment -->
    <link name="left_fr3_link0">
        <visual>
            <geometry>
                <mesh filename="package://franka_description/meshes/visual/link0.dae" />
            </geometry>
        </visual>
        <collision>
            <geometry>
                <mesh filename="package://franka_description/meshes/collision/link0.stl" />
            </geometry>
        </collision>
        <inertial>
            <mass value="0.1" />
            <origin xyz="0 0 0" rpy="0 0 0" />
            <inertia ixx="0.03" iyy="0.03" izz="0.03" ixy="0.0" ixz="0.0" iyz="0.0" />
        </inertial>
    </link>
    <!-- sub-link defining coarse geometries of real robot's internal self-collision -->
    <link name="left_fr3_link0_sc">
        <collision>
            <origin rpy="0 1.5707963267948966 0" xyz="-0.075 0 0.06" />
            <geometry>
                <cylinder length="0.03" radius="0.06" />
            </geometry>
        </collision>
        <collision>
            <origin xyz="-0.06 0 0.06" />
            <geometry>
                <sphere radius="0.06" />
            </geometry>
        </collision>
        <collision>
            <origin xyz="-0.09 0 0.06" />
            <geometry>
                <sphere radius="0.06" />
            </geometry>
        </collision>
        <inertial>
            <mass value="0.1" />
            <origin xyz="0 0 0" rpy="0 0 0" />
            <inertia ixx="0.03" iyy="0.03" izz="0.03" ixy="0.0" ixz="0.0" iyz="0.0" />
        </inertial>
    </link>
    <!-- fixed joint between both sub-links -->
    <joint name="left_fr3_link0_sc_joint" type="fixed">
        <origin rpy="0 0 0" />
        <parent link="left_fr3_link0" />
        <child link="left_fr3_link0_sc" />
    </joint>
    <!-- sub-link defining detailed meshes for collision with environment -->
    <link name="left_fr3_link1">
        <visual>
            <geometry>
                <mesh filename="package://franka_description/meshes/visual/link1.dae" />
            </geometry>
        </visual>
        <collision>
            <geometry>
                <mesh filename="package://franka_description/meshes/collision/link1.stl" />
            </geometry>
        </collision>
        <inertial>
            <mass value="0.1" />
            <origin xyz="0 0 0" rpy="0 0 0" />
            <inertia ixx="0.03" iyy="0.03" izz="0.03" ixy="0.0" ixz="0.0" iyz="0.0" />
        </inertial>
    </link>
    <!-- sub-link defining coarse geometries of real robot's internal self-collision -->
    <link name="left_fr3_link1_sc">
        <collision>
            <origin rpy="0 0 0" xyz="0 0 -0.1915" />
            <geometry>
                <cylinder length="0.283" radius="0.06" />
            </geometry>
        </collision>
        <collision>
            <origin xyz="0 0 -0.05000000000000002" />
            <geometry>
                <sphere radius="0.06" />
            </geometry>
        </collision>
        <collision>
            <origin xyz="0 0 -0.33299999999999996" />
            <geometry>
                <sphere radius="0.06" />
            </geometry>
        </collision>
        <inertial>
            <mass value="0.1" />
            <origin xyz="0 0 0" rpy="0 0 0" />
            <inertia ixx="0.03" iyy="0.03" izz="0.03" ixy="0.0" ixz="0.0" iyz="0.0" />
        </inertial>
    </link>
    <!-- fixed joint between both sub-links -->
    <joint name="left_fr3_link1_sc_joint" type="fixed">
        <origin rpy="0 0 0" />
        <parent link="left_fr3_link1" />
        <child link="left_fr3_link1_sc" />
    </joint>
    <joint name="left_fr3_joint1" type="revolute">
        <origin rpy="0 0 0" xyz="0 0 0.333" />
        <parent link="left_fr3_link0" />
        <child link="left_fr3_link1" />
        <axis xyz="0 0 1" />
        <limit effort="87.0" lower="-2.3093" upper="2.3093" velocity="2.0" />
        <safety_controller k_position="100.0" k_velocity="40.0" soft_lower_limit="-2.3093" soft_upper_limit="2.3093" />
        <dynamics D="1" K="7000" damping="0.003" friction="0.0" mu_coulomb="0" mu_viscous="16" />
    </joint>
    <!-- sub-link defining detailed meshes for collision with environment -->
    <link name="left_fr3_link2">
        <visual>
            <geometry>
                <mesh filename="package://franka_description/meshes/visual/link2.dae" />
            </geometry>
        </visual>
        <collision>
            <geometry>
                <mesh filename="package://franka_description/meshes/collision/link2.stl" />
            </geometry>
        </collision>
        <inertial>
            <mass value="0.1" />
            <origin xyz="0 0 0" rpy="0 0 0" />
            <inertia ixx="0.03" iyy="0.03" izz="0.03" ixy="0.0" ixz="0.0" iyz="0.0" />
        </inertial>
    </link>
    <!-- sub-link defining coarse geometries of real robot's internal self-collision -->
    <link name="left_fr3_link2_sc">
        <collision>
            <origin rpy="0 0 0" xyz="0 0 0" />
            <geometry>
                <cylinder length="0.12" radius="0.06" />
            </geometry>
        </collision>
        <collision>
            <origin xyz="0 0 0.06" />
            <geometry>
                <sphere radius="0.06" />
            </geometry>
        </collision>
        <collision>
            <origin xyz="0 0 -0.06" />
            <geometry>
                <sphere radius="0.06" />
            </geometry>
        </collision>
        <inertial>
            <mass value="0.1" />
            <origin xyz="0 0 0" rpy="0 0 0" />
            <inertia ixx="0.03" iyy="0.03" izz="0.03" ixy="0.0" ixz="0.0" iyz="0.0" />
        </inertial>
    </link>
    <!-- fixed joint between both sub-links -->
    <joint name="left_fr3_link2_sc_joint" type="fixed">
        <origin rpy="0 0 0" />
        <parent link="left_fr3_link2" />
        <child link="left_fr3_link2_sc" />
    </joint>
    <joint name="left_fr3_joint2" type="revolute">
        <origin rpy="-1.5707963267948966 0 0" xyz="0 0 0" />
        <parent link="left_fr3_link1" />
        <child link="left_fr3_link2" />
        <axis xyz="0 0 1" />
        <limit effort="87.0" lower="-1.5133" upper="1.5133" velocity="1.0" />
        <safety_controller k_position="100.0" k_velocity="40.0" soft_lower_limit="-1.5133" soft_upper_limit="1.5133" />
        <dynamics D="1" K="7000" damping="0.003" friction="0.0" mu_coulomb="0" mu_viscous="16" />
    </joint>
    <!-- sub-link defining detailed meshes for collision with environment -->
    <link name="left_fr3_link3">
        <visual>
            <geometry>
                <mesh filename="package://franka_description/meshes/visual/link3.dae" />
            </geometry>
        </visual>
        <collision>
            <geometry>
                <mesh filename="package://franka_description/meshes/collision/link3.stl" />
            </geometry>
        </collision>
        <inertial>
            <mass value="0.1" />
            <origin xyz="0 0 0" rpy="0 0 0" />
            <inertia ixx="0.03" iyy="0.03" izz="0.03" ixy="0.0" ixz="0.0" iyz="0.0" />
        </inertial>
    </link>
    <!-- sub-link defining coarse geometries of real robot's internal self-collision -->
    <link name="left_fr3_link3_sc">
        <collision>
            <origin rpy="0 0 0" xyz="0 0 -0.145" />
            <geometry>
                <cylinder length="0.15" radius="0.06" />
            </geometry>
        </collision>
        <collision>
            <origin xyz="0 0 -0.06999999999999999" />
            <geometry>
                <sphere radius="0.06" />
            </geometry>
        </collision>
        <collision>
            <origin xyz="0 0 -0.21999999999999997" />
            <geometry>
                <sphere radius="0.06" />
            </geometry>
        </collision>
        <inertial>
            <mass value="0.1" />
            <origin xyz="0 0 0" rpy="0 0 0" />
            <inertia ixx="0.03" iyy="0.03" izz="0.03" ixy="0.0" ixz="0.0" iyz="0.0" />
        </inertial>
    </link>
    <!-- fixed joint between both sub-links -->
    <joint name="left_fr3_link3_sc_joint" type="fixed">
        <origin rpy="0 0 0" />
        <parent link="left_fr3_link3" />
        <child link="left_fr3_link3_sc" />
    </joint>
    <joint name="left_fr3_joint3" type="revolute">
        <origin rpy="1.5707963267948966 0 0" xyz="0 -0.316 0" />
        <parent link="left_fr3_link2" />
        <child link="left_fr3_link3" />
        <axis xyz="0 0 1" />
        <limit effort="87.0" lower="-2.4937" upper="2.4937" velocity="1.5" />
        <safety_controller k_position="100.0" k_velocity="40.0" soft_lower_limit="-2.4937" soft_upper_limit="2.4937" />
        <dynamics D="1" K="7000" damping="0.003" friction="0.0" mu_coulomb="0" mu_viscous="16" />
    </joint>
    <!-- sub-link defining detailed meshes for collision with environment -->
    <link name="left_fr3_link4">
        <visual>
            <geometry>
                <mesh filename="package://franka_description/meshes/visual/link4.dae" />
            </geometry>
        </visual>
        <collision>
            <geometry>
                <mesh filename="package://franka_description/meshes/collision/link4.stl" />
            </geometry>
        </collision>
        <inertial>
            <mass value="0.1" />
            <origin xyz="0 0 0" rpy="0 0 0" />
            <inertia ixx="0.03" iyy="0.03" izz="0.03" ixy="0.0" ixz="0.0" iyz="0.0" />
        </inertial>
    </link>
    <!-- sub-link defining coarse geometries of real robot's internal self-collision -->
    <link name="left_fr3_link4_sc">
        <collision>
            <origin rpy="0 0 0" xyz="0 0 0" />
            <geometry>
                <cylinder length="0.12" radius="0.06" />
            </geometry>
        </collision>
        <collision>
            <origin xyz="0 0 0.06" />
            <geometry>
                <sphere radius="0.06" />
            </geometry>
        </collision>
        <collision>
            <origin xyz="0 0 -0.06" />
            <geometry>
                <sphere radius="0.06" />
            </geometry>
        </collision>
        <inertial>
            <mass value="0.1" />
            <origin xyz="0 0 0" rpy="0 0 0" />
            <inertia ixx="0.03" iyy="0.03" izz="0.03" ixy="0.0" ixz="0.0" iyz="0.0" />
        </inertial>
    </link>
    <!-- fixed joint between both sub-links -->
    <joint name="left_fr3_link4_sc_joint" type="fixed">
        <origin rpy="0 0 0" />
        <parent link="left_fr3_link4" />
        <child link="left_fr3_link4_sc" />
    </joint>
    <joint name="left_fr3_joint4" type="revolute">
        <origin rpy="1.5707963267948966 0 0" xyz="0.0825 0 0" />
        <parent link="left_fr3_link3" />
        <child link="left_fr3_link4" />
        <axis xyz="0 0 1" />
        <limit effort="87.0" lower="-2.7478" upper="-0.4461" velocity="1.25" />
        <safety_controller k_position="100.0" k_velocity="40.0" soft_lower_limit="-2.7478" soft_upper_limit="-0.4461" />
        <dynamics D="1" K="7000" damping="0.003" friction="0.0" mu_coulomb="0" mu_viscous="16" />
    </joint>
    <!-- sub-link defining detailed meshes for collision with environment -->
    <link name="left_fr3_link5">
        <visual>
            <geometry>
                <mesh filename="package://franka_description/meshes/visual/link5.dae" />
            </geometry>
        </visual>
        <collision>
            <geometry>
                <mesh filename="package://franka_description/meshes/collision/link5.stl" />
            </geometry>
        </collision>
        <inertial>
            <mass value="0.1" />
            <origin xyz="0 0 0" rpy="0 0 0" />
            <inertia ixx="0.03" iyy="0.03" izz="0.03" ixy="0.0" ixz="0.0" iyz="0.0" />
        </inertial>
    </link>
    <!-- sub-link defining coarse geometries of real robot's internal self-collision -->
    <link name="left_fr3_link5_sc">
        <collision>
            <origin rpy="0 0 0" xyz="0 0 -0.26" />
            <geometry>
                <cylinder length="0.1" radius="0.06" />
            </geometry>
        </collision>
        <collision>
            <origin xyz="0 0 -0.21000000000000002" />
            <geometry>
                <sphere radius="0.06" />
            </geometry>
        </collision>
        <collision>
            <origin xyz="0 0 -0.31" />
            <geometry>
                <sphere radius="0.06" />
            </geometry>
        </collision>
        <collision>
            <origin rpy="0 0 0.08" xyz="0 0.08 -0.13" />
            <geometry>
                <cylinder length="0.14" radius="0.025" />
            </geometry>
        </collision>
        <collision>
            <origin xyz="0 0.08 -0.06" />
            <geometry>
                <sphere radius="0.025" />
            </geometry>
        </collision>
        <collision>
            <origin xyz="0 0.08 -0.2" />
            <geometry>
                <sphere radius="0.025" />
            </geometry>
        </collision>
        <inertial>
            <mass value="0.1" />
            <origin xyz="0 0 0" rpy="0 0 0" />
            <inertia ixx="0.03" iyy="0.03" izz="0.03" ixy="0.0" ixz="0.0" iyz="0.0" />
        </inertial>
    </link>
    <!-- fixed joint between both sub-links -->
    <joint name="left_fr3_link5_sc_joint" type="fixed">
        <origin rpy="0 0 0" />
        <parent link="left_fr3_link5" />
        <child link="left_fr3_link5_sc" />
    </joint>
    <joint name="left_fr3_joint5" type="revolute">
        <origin rpy="-1.5707963267948966 0 0" xyz="-0.0825 0.384 0" />
        <parent link="left_fr3_link4" />
        <child link="left_fr3_link5" />
        <axis xyz="0 0 1" />
        <limit effort="12.0" lower="-2.48" upper="2.48" velocity="3.0" />
        <safety_controller k_position="100.0" k_velocity="40.0" soft_lower_limit="-2.48" soft_upper_limit="2.48" />
        <dynamics D="1" K="7000" damping="0.003" friction="0.0" mu_coulomb="0" mu_viscous="16" />
    </joint>
    <!-- sub-link defining detailed meshes for collision with environment -->
    <link name="left_fr3_link6">
        <visual>
            <geometry>
                <mesh filename="package://franka_description/meshes/visual/link6.dae" />
            </geometry>
        </visual>
        <collision>
            <geometry>
                <mesh filename="package://franka_description/meshes/collision/link6.stl" />
            </geometry>
        </collision>
        <inertial>
            <mass value="0.1" />
            <origin xyz="0 0 0" rpy="0 0 0" />
            <inertia ixx="0.03" iyy="0.03" izz="0.03" ixy="0.0" ixz="0.0" iyz="0.0" />
        </inertial>
    </link>
    <!-- sub-link defining coarse geometries of real robot's internal self-collision -->
    <link name="left_fr3_link6_sc">
        <collision>
            <origin rpy="0 0 0" xyz="0 0 -0.03" />
            <geometry>
                <cylinder length="0.08" radius="0.05" />
            </geometry>
        </collision>
        <collision>
            <origin xyz="0 0 0.010000000000000002" />
            <geometry>
                <sphere radius="0.05" />
            </geometry>
        </collision>
        <collision>
            <origin xyz="0 0 -0.07" />
            <geometry>
                <sphere radius="0.05" />
            </geometry>
        </collision>
        <inertial>
            <mass value="0.1" />
            <origin xyz="0 0 0" rpy="0 0 0" />
            <inertia ixx="0.03" iyy="0.03" izz="0.03" ixy="0.0" ixz="0.0" iyz="0.0" />
        </inertial>
    </link>
    <!-- fixed joint between both sub-links -->
    <joint name="left_fr3_link6_sc_joint" type="fixed">
        <origin rpy="0 0 0" />
        <parent link="left_fr3_link6" />
        <child link="left_fr3_link6_sc" />
    </joint>
    <joint name="left_fr3_joint6" type="revolute">
        <origin rpy="1.5707963267948966 0 0" xyz="0 0 0" />
        <parent link="left_fr3_link5" />
        <child link="left_fr3_link6" />
        <axis xyz="0 0 1" />
        <limit effort="12.0" lower="0.8521" upper="4.2094" velocity="1.5" />
        <safety_controller k_position="100.0" k_velocity="40.0" soft_lower_limit="0.8521" soft_upper_limit="4.2094" />
        <dynamics D="1" K="7000" damping="0.003" friction="0.0" mu_coulomb="0" mu_viscous="16" />
    </joint>
    <!-- sub-link defining detailed meshes for collision with environment -->
    <link name="left_fr3_link7">
        <visual>
            <geometry>
                <mesh filename="package://franka_description/meshes/visual/link7.dae" />
            </geometry>
        </visual>
        <collision>
            <geometry>
                <mesh filename="package://franka_description/meshes/collision/link7.stl" />
            </geometry>
        </collision>
        <inertial>
            <mass value="0.1" />
            <origin xyz="0 0 0" rpy="0 0 0" />
            <inertia ixx="0.03" iyy="0.03" izz="0.03" ixy="0.0" ixz="0.0" iyz="0.0" />
        </inertial>
    </link>
    <!-- sub-link defining coarse geometries of real robot's internal self-collision -->
    <link name="left_fr3_link7_sc">
        <collision>
            <origin rpy="0 0 0" xyz="0 0 0.01" />
            <geometry>
                <cylinder length="0.14" radius="0.04" />
            </geometry>
        </collision>
        <collision>
            <origin xyz="0 0 0.08" />
            <geometry>
                <sphere radius="0.04" />
            </geometry>
        </collision>
        <collision>
            <origin xyz="0 0 -0.060000000000000005" />
            <geometry>
                <sphere radius="0.04" />
            </geometry>
        </collision>
        <collision>
            <origin rpy="0 1.5707963267948966 0" xyz="0.06 0 0.082" />
            <geometry>
                <cylinder length="0.01" radius="0.03" />
            </geometry>
        </collision>
        <collision>
            <origin xyz="0.065 0 0.082" />
            <geometry>
                <sphere radius="0.03" />
            </geometry>
        </collision>
        <collision>
            <origin xyz="0.055 0 0.082" />
            <geometry>
                <sphere radius="0.03" />
            </geometry>
        </collision>
        <inertial>
            <mass value="0.1" />
            <origin xyz="0 0 0" rpy="0 0 0" />
            <inertia ixx="0.03" iyy="0.03" izz="0.03" ixy="0.0" ixz="0.0" iyz="0.0" />
        </inertial>
    </link>
    <!-- fixed joint between both sub-links -->
    <joint name="left_fr3_link7_sc_joint" type="fixed">
        <origin rpy="0 0 0.7853981633974483" />
        <parent link="left_fr3_link7" />
        <child link="left_fr3_link7_sc" />
    </joint>
    <joint name="left_fr3_joint7" type="revolute">
        <origin rpy="1.5707963267948966 0 0" xyz="0.088 0 0" />
        <parent link="left_fr3_link6" />
        <child link="left_fr3_link7" />
        <axis xyz="0 0 1" />
        <limit effort="12.0" lower="-2.6895" upper="2.6895" velocity="3.0" />
        <safety_controller k_position="100.0" k_velocity="40.0" soft_lower_limit="-2.6895" soft_upper_limit="2.6895" />
        <dynamics D="1" K="7000" damping="0.003" friction="0.0" mu_coulomb="0" mu_viscous="16" />
    </joint>
    <link name="left_fr3_link8" />
    <joint name="left_fr3_joint8" type="fixed">
        <origin rpy="0 0 0" xyz="0 0 0.107" />
        <parent link="left_fr3_link7" />
        <child link="left_fr3_link8" />
    </joint>
    <joint name="left_fr3_hand_joint" type="fixed">
        <parent link="left_fr3_link8" />
        <child link="left_fr3_hand" />
        <origin rpy="0 0 -0.785398163" xyz="0 0 0.002" />
    </joint>
    <!-- sub-link defining detailed meshes for collision with environment -->
    <link name="left_fr3_hand">
        <visual>
            <geometry>
                <mesh filename="package://franka_description/meshes/visual/hand.dae" />
            </geometry>
        </visual>
        <collision>
            <geometry>
                <mesh filename="package://franka_description/meshes/collision/hand.stl" />
            </geometry>
        </collision>
        <inertial>
            <mass value="0.1" />
            <origin xyz="0 0 0" rpy="0 0 0" />
            <inertia ixx="0.03" iyy="0.03" izz="0.03" ixy="0.0" ixz="0.0" iyz="0.0" />
        </inertial>
    </link>
    <!-- sub-link defining coarse geometries of real robot's internal self-collision -->
    <link name="left_fr3_hand_sc">
        <collision>
            <origin rpy="1.5707963267948966 0 0" xyz="0 0 0.04" />
            <geometry>
                <cylinder length="0.1" radius="0.04" />
            </geometry>
        </collision>
        <collision>
            <origin xyz="0 0.05 0.04" />
            <geometry>
                <sphere radius="0.04" />
            </geometry>
        </collision>
        <collision>
            <origin xyz="0 -0.05 0.04" />
            <geometry>
                <sphere radius="0.04" />
            </geometry>
        </collision>
        <collision>
            <origin rpy="1.5707963267948966 0 0" xyz="0 0 0.1" />
            <geometry>
                <cylinder length="0.1" radius="0.02" />
            </geometry>
        </collision>
        <collision>
            <origin xyz="0 0.05 0.1" />
            <geometry>
                <sphere radius="0.02" />
            </geometry>
        </collision>
        <collision>
            <origin xyz="0 -0.05 0.1" />
            <geometry>
                <sphere radius="0.02" />
            </geometry>
        </collision>
        <inertial>
            <mass value="0.1" />
            <origin xyz="0 0 0" rpy="0 0 0" />
            <inertia ixx="0.03" iyy="0.03" izz="0.03" ixy="0.0" ixz="0.0" iyz="0.0" />
        </inertial>
    </link>
    <!-- fixed joint between both sub-links -->
    <joint name="left_fr3_hand_sc_joint" type="fixed">
        <origin rpy="0 0 0" />
        <parent link="left_fr3_hand" />
        <child link="left_fr3_hand_sc" />
    </joint>
    <!-- Define the hand_tcp frame -->
    <link name="left_fr3_hand_tcp" />
    <joint name="left_fr3_hand_tcp_joint" type="fixed">
        <origin rpy="0 0 0" xyz="0 0 0.1034" />
        <parent link="left_fr3_hand" />
        <child link="left_fr3_hand_tcp" />
    </joint>
    <link name="left_fr3_leftfinger">
        <visual>
            <geometry>
                <mesh filename="package://franka_description/meshes/visual/finger.dae" />
            </geometry>
        </visual>
        <!-- screw mount -->
        <collision>
            <origin rpy="0 0 0" xyz="0 18.5e-3 11e-3" />
            <geometry>
                <box size="22e-3 15e-3 20e-3" />
            </geometry>
        </collision>
        <!-- cartriage sledge -->
        <collision>
            <origin rpy="0 0 0" xyz="0 6.8e-3 2.2e-3" />
            <geometry>
                <box size="22e-3 8.8e-3 3.8e-3" />
            </geometry>
        </collision>
        <!-- diagonal finger -->
        <collision>
            <origin rpy="0.5235987755982988 0 0" xyz="0 15.9e-3 28.35e-3" />
            <geometry>
                <box size="17.5e-3 7e-3 23.5e-3" />
            </geometry>
        </collision>
        <!-- rubber tip with which to grasp -->
        <collision>
            <origin rpy="0 0 0" xyz="0 7.58e-3 45.25e-3" />
            <geometry>
                <box size="17.5e-3 15.2e-3 18.5e-3" />
            </geometry>
        </collision>
        <inertial>
            <mass value="0.1" />
            <origin xyz="0 0 0" rpy="0 0 0" />
            <inertia ixx="0.03" iyy="0.03" izz="0.03" ixy="0.0" ixz="0.0" iyz="0.0" />
        </inertial>
    </link>
    <link name="left_fr3_rightfinger">
        <visual>
            <origin rpy="0 0 3.141592653589793" xyz="0 0 0" />
            <geometry>
                <mesh filename="package://franka_description/meshes/visual/finger.dae" />
            </geometry>
        </visual>
        <!-- screw mount -->
        <collision>
            <origin rpy="0 0 0" xyz="0 -18.5e-3 11e-3" />
            <geometry>
                <box size="22e-3 15e-3 20e-3" />
            </geometry>
        </collision>
        <!-- cartriage sledge -->
        <collision>
            <origin rpy="0 0 0" xyz="0 -6.8e-3 2.2e-3" />
            <geometry>
                <box size="22e-3 8.8e-3 3.8e-3" />
            </geometry>
        </collision>
        <!-- diagonal finger -->
        <collision>
            <origin rpy="-0.5235987755982988 0 0" xyz="0 -15.9e-3 28.35e-3" />
            <geometry>
                <box size="17.5e-3 7e-3 23.5e-3" />
            </geometry>
        </collision>
        <!-- rubber tip with which to grasp -->
        <collision>
            <origin rpy="0 0 0" xyz="0 -7.58e-3 45.25e-3" />
            <geometry>
                <box size="17.5e-3 15.2e-3 18.5e-3" />
            </geometry>
        </collision>
        <inertial>
            <mass value="0.1" />
            <origin xyz="0 0 0" rpy="0 0 0" />
            <inertia ixx="0.03" iyy="0.03" izz="0.03" ixy="0.0" ixz="0.0" iyz="0.0" />
        </inertial>
    </link>
    <joint name="left_fr3_finger_joint1" type="prismatic">
        <parent link="left_fr3_hand" />
        <child link="left_fr3_leftfinger" />
        <origin rpy="0 0 0" xyz="0 0 0.0584" />
        <axis xyz="0 1 0" />
        <limit effort="100" lower="0.0" upper="0.04" velocity="0.2" />
        <dynamics damping="0.3" />
    </joint>
    <joint name="left_fr3_finger_joint2" type="prismatic">
        <parent link="left_fr3_hand" />
        <child link="left_fr3_rightfinger" />
        <origin rpy="0 0 0" xyz="0 0 0.0584" />
        <axis xyz="0 -1 0" />
        <limit effort="100" lower="0.0" upper="0.04" velocity="0.2" />
        <mimic joint="left_fr3_finger_joint1" />
        <dynamics damping="0.3" />
    </joint>
    <link name="left_camera_bracket">
        <inertial>
            <origin rpy="0 0 0" xyz="0.0134438110340833 -0.168362228593174 0.448374390946475" />
            <mass value="17.8" />
            <inertia ixx="6.25233742851433" ixy="-0.52125829292522" ixz="-0.826110619533779" iyy="4.1685965211151" iyz="0.217129723015581" izz="5.22932283924632" />
        </inertial>
        <visual>
            <origin rpy="0 0 0" xyz="0 0 0" />
            <geometry>
                <mesh filename="package://mr1000_dual_fr3_description/meshes/camera_bracket.STL" />
            </geometry>
            <material name="">
                <color rgba="0.898039215686275 0.917647058823529 0.929411764705882 1" />
            </material>
        </visual>
        <collision>
            <origin rpy="0 0 0" xyz="0 0 0" />
            <geometry>
                <mesh filename="package://mr1000_dual_fr3_description/meshes/camera_bracket.STL" />
            </geometry>
        </collision>
    </link>
    <joint name="left_camera_bracket_joint" type="fixed">
        <origin rpy="0 0 -0.785398163" xyz="0 0 0" />
        <parent link="left_fr3_link8" />
        <child link="left_camera_bracket" />
    </joint>
    <!-- camera body, with origin at bottom screw mount -->
    <joint name="left_camera_joint" type="fixed">
        <origin rpy="3.14159265358979 -1.5707963267949 0" xyz="0.0829950975679638 0 0.01215" />
        <parent link="left_camera_bracket" />
        <child link="left_camera_bottom_screw_frame" />
    </joint>
    <link name="left_camera_bottom_screw_frame" />
    <joint name="left_camera_link_joint" type="fixed">
        <origin rpy="0 0 0" xyz="0.010600000000000002 0.0175 0.0125" />
        <parent link="left_camera_bottom_screw_frame" />
        <child link="left_camera_link" />
    </joint>
    <link name="left_camera_link">
        <visual>
            <!-- the mesh origin is at front plate in between the two infrared camera axes -->
            <origin rpy="1.5707963267948966 0 1.5707963267948966" xyz="0.0043 -0.0175 0" />
            <geometry>
                <mesh filename="package://realsense2_description/meshes/d435.dae" />
            </geometry>
        </visual>
        <collision>
            <origin rpy="0 0 0" xyz="0 -0.0175 0" />
            <geometry>
                <box size="0.02505 0.09 0.025" />
            </geometry>
        </collision>
        <inertial>
            <!-- The following are not reliable values, and should not be used for modeling -->
            <mass value="0.072" />
            <origin xyz="0 0 0" rpy="0 0 0" />
            <inertia ixx="0.003881243" ixy="0.0" ixz="0.0" iyy="0.000498940" iyz="0.0" izz="0.003879257" />
        </inertial>
    </link>
    <!-- camera depth joints and links -->
    <joint name="left_camera_depth_joint" type="fixed">
        <origin rpy="0 0 0" xyz="0 0 0" />
        <parent link="left_camera_link" />
        <child link="left_camera_depth_frame" />
    </joint>
    <link name="left_camera_depth_frame" />
    <joint name="left_camera_depth_optical_joint" type="fixed">
        <origin rpy="-1.5707963267948966 0 -1.5707963267948966" xyz="0 0 0" />
        <parent link="left_camera_depth_frame" />
        <child link="left_camera_depth_optical_frame" />
    </joint>
    <link name="left_camera_depth_optical_frame" />
    <!-- camera left IR joints and links -->
    <joint name="left_camera_infra1_joint" type="fixed">
        <origin rpy="0 0 0" xyz="0 0.0 0" />
        <parent link="left_camera_link" />
        <child link="left_camera_infra1_frame" />
    </joint>
    <link name="left_camera_infra1_frame" />
    <joint name="left_camera_infra1_optical_joint" type="fixed">
        <origin rpy="-1.5707963267948966 0 -1.5707963267948966" xyz="0 0 0" />
        <parent link="left_camera_infra1_frame" />
        <child link="left_camera_infra1_optical_frame" />
    </joint>
    <link name="left_camera_infra1_optical_frame" />
    <!-- camera right IR joints and links -->
    <joint name="left_camera_infra2_joint" type="fixed">
        <origin rpy="0 0 0" xyz="0 -0.05 0" />
        <parent link="left_camera_link" />
        <child link="left_camera_infra2_frame" />
    </joint>
    <link name="left_camera_infra2_frame" />
    <joint name="left_camera_infra2_optical_joint" type="fixed">
        <origin rpy="-1.5707963267948966 0 -1.5707963267948966" xyz="0 0 0" />
        <parent link="left_camera_infra2_frame" />
        <child link="left_camera_infra2_optical_frame" />
    </joint>
    <link name="left_camera_infra2_optical_frame" />
    <!-- camera color joints and links -->
    <joint name="left_camera_color_joint" type="fixed">
        <origin rpy="0 0 0" xyz="0 0.015 0" />
        <parent link="left_camera_link" />
        <child link="left_camera_color_frame" />
    </joint>
    <link name="left_camera_color_frame" />
    <joint name="left_camera_color_optical_joint" type="fixed">
        <origin rpy="-1.5707963267948966 0 -1.5707963267948966" xyz="0 0 0" />
        <parent link="left_camera_color_frame" />
        <child link="left_camera_color_optical_frame" />
    </joint>
    <link name="left_camera_color_optical_frame" />
    <link name="left_camera_accel_frame" />
    <link name="left_camera_accel_optical_frame" />
    <link name="left_camera_gyro_frame" />
    <link name="left_camera_gyro_optical_frame" />
    <joint name="left_camera_accel_joint" type="fixed">
        <origin rpy="0 0 0" xyz="-0.01174 -0.00552 0.0051" />
        <parent link="left_camera_link" />
        <child link="left_camera_accel_frame" />
    </joint>
    <joint name="left_camera_accel_optical_joint" type="fixed">
        <origin rpy="-1.5707963267948966 0 -1.5707963267948966" xyz="0 0 0" />
        <parent link="left_camera_accel_frame" />
        <child link="left_camera_accel_optical_frame" />
    </joint>
    <joint name="left_camera_gyro_joint" type="fixed">
        <origin rpy="0 0 0" xyz="-0.01174 -0.00552 0.0051" />
        <parent link="left_camera_link" />
        <child link="left_camera_gyro_frame" />
    </joint>
    <joint name="left_camera_gyro_optical_joint" type="fixed">
        <origin rpy="-1.5707963267948966 0 -1.5707963267948966" xyz="0 0 0" />
        <parent link="left_camera_gyro_frame" />
        <child link="left_camera_gyro_optical_frame" />
    </joint>
    <!-- right -->
    <!-- 手动创建franka连接parent的joint，防止franka的urdf自动创建parent link -->
    <joint name="right_fr3_base_link_joint" type="fixed">
        <parent link="base_link" />
        <child link="right_fr3_link0" />
        <origin rpy="1.5707963267949 -1.5707963267949 0" xyz="0.153000000000001 -0.0599999999999994 0.968500000000001" />
    </joint>
    <!-- sub-link defining detailed meshes for collision with environment -->
    <link name="right_fr3_link0">
        <visual>
            <geometry>
                <mesh filename="package://franka_description/meshes/visual/link0.dae" />
            </geometry>
        </visual>
        <collision>
            <geometry>
                <mesh filename="package://franka_description/meshes/collision/link0.stl" />
            </geometry>
        </collision>
        <inertial>
            <mass value="0.1" />
            <origin xyz="0 0 0" rpy="0 0 0" />
            <inertia ixx="0.03" iyy="0.03" izz="0.03" ixy="0.0" ixz="0.0" iyz="0.0" />
        </inertial>
    </link>
    <!-- sub-link defining coarse geometries of real robot's internal self-collision -->
    <link name="right_fr3_link0_sc">
        <collision>
            <origin rpy="0 1.5707963267948966 0" xyz="-0.075 0 0.06" />
            <geometry>
                <cylinder length="0.03" radius="0.06" />
            </geometry>
        </collision>
        <collision>
            <origin xyz="-0.06 0 0.06" />
            <geometry>
                <sphere radius="0.06" />
            </geometry>
        </collision>
        <collision>
            <origin xyz="-0.09 0 0.06" />
            <geometry>
                <sphere radius="0.06" />
            </geometry>
        </collision>
        <inertial>
            <mass value="0.1" />
            <origin xyz="0 0 0" rpy="0 0 0" />
            <inertia ixx="0.03" iyy="0.03" izz="0.03" ixy="0.0" ixz="0.0" iyz="0.0" />
        </inertial>
    </link>
    <!-- fixed joint between both sub-links -->
    <joint name="right_fr3_link0_sc_joint" type="fixed">
        <origin rpy="0 0 0" />
        <parent link="right_fr3_link0" />
        <child link="right_fr3_link0_sc" />
    </joint>
    <!-- sub-link defining detailed meshes for collision with environment -->
    <link name="right_fr3_link1">
        <visual>
            <geometry>
                <mesh filename="package://franka_description/meshes/visual/link1.dae" />
            </geometry>
        </visual>
        <collision>
            <geometry>
                <mesh filename="package://franka_description/meshes/collision/link1.stl" />
            </geometry>
        </collision>
        <inertial>
            <mass value="0.1" />
            <origin xyz="0 0 0" rpy="0 0 0" />
            <inertia ixx="0.03" iyy="0.03" izz="0.03" ixy="0.0" ixz="0.0" iyz="0.0" />
        </inertial>
    </link>
    <!-- sub-link defining coarse geometries of real robot's internal self-collision -->
    <link name="right_fr3_link1_sc">
        <collision>
            <origin rpy="0 0 0" xyz="0 0 -0.1915" />
            <geometry>
                <cylinder length="0.283" radius="0.06" />
            </geometry>
        </collision>
        <collision>
            <origin xyz="0 0 -0.05000000000000002" />
            <geometry>
                <sphere radius="0.06" />
            </geometry>
        </collision>
        <collision>
            <origin xyz="0 0 -0.33299999999999996" />
            <geometry>
                <sphere radius="0.06" />
            </geometry>
        </collision>
        <inertial>
            <mass value="0.1" />
            <origin xyz="0 0 0" rpy="0 0 0" />
            <inertia ixx="0.03" iyy="0.03" izz="0.03" ixy="0.0" ixz="0.0" iyz="0.0" />
        </inertial>
    </link>
    <!-- fixed joint between both sub-links -->
    <joint name="right_fr3_link1_sc_joint" type="fixed">
        <origin rpy="0 0 0" />
        <parent link="right_fr3_link1" />
        <child link="right_fr3_link1_sc" />
    </joint>
    <joint name="right_fr3_joint1" type="revolute">
        <origin rpy="0 0 0" xyz="0 0 0.333" />
        <parent link="right_fr3_link0" />
        <child link="right_fr3_link1" />
        <axis xyz="0 0 1" />
        <limit effort="87.0" lower="-2.3093" upper="2.3093" velocity="2.0" />
        <safety_controller k_position="100.0" k_velocity="40.0" soft_lower_limit="-2.3093" soft_upper_limit="2.3093" />
        <dynamics D="1" K="7000" damping="0.003" friction="0.0" mu_coulomb="0" mu_viscous="16" />
    </joint>
    <!-- sub-link defining detailed meshes for collision with environment -->
    <link name="right_fr3_link2">
        <visual>
            <geometry>
                <mesh filename="package://franka_description/meshes/visual/link2.dae" />
            </geometry>
        </visual>
        <collision>
            <geometry>
                <mesh filename="package://franka_description/meshes/collision/link2.stl" />
            </geometry>
        </collision>
        <inertial>
            <mass value="0.1" />
            <origin xyz="0 0 0" rpy="0 0 0" />
            <inertia ixx="0.03" iyy="0.03" izz="0.03" ixy="0.0" ixz="0.0" iyz="0.0" />
        </inertial>
    </link>
    <!-- sub-link defining coarse geometries of real robot's internal self-collision -->
    <link name="right_fr3_link2_sc">
        <collision>
            <origin rpy="0 0 0" xyz="0 0 0" />
            <geometry>
                <cylinder length="0.12" radius="0.06" />
            </geometry>
        </collision>
        <collision>
            <origin xyz="0 0 0.06" />
            <geometry>
                <sphere radius="0.06" />
            </geometry>
        </collision>
        <collision>
            <origin xyz="0 0 -0.06" />
            <geometry>
                <sphere radius="0.06" />
            </geometry>
        </collision>
        <inertial>
            <mass value="0.1" />
            <origin xyz="0 0 0" rpy="0 0 0" />
            <inertia ixx="0.03" iyy="0.03" izz="0.03" ixy="0.0" ixz="0.0" iyz="0.0" />
        </inertial>
    </link>
    <!-- fixed joint between both sub-links -->
    <joint name="right_fr3_link2_sc_joint" type="fixed">
        <origin rpy="0 0 0" />
        <parent link="right_fr3_link2" />
        <child link="right_fr3_link2_sc" />
    </joint>
    <joint name="right_fr3_joint2" type="revolute">
        <origin rpy="-1.5707963267948966 0 0" xyz="0 0 0" />
        <parent link="right_fr3_link1" />
        <child link="right_fr3_link2" />
        <axis xyz="0 0 1" />
        <limit effort="87.0" lower="-1.5133" upper="1.5133" velocity="1.0" />
        <safety_controller k_position="100.0" k_velocity="40.0" soft_lower_limit="-1.5133" soft_upper_limit="1.5133" />
        <dynamics D="1" K="7000" damping="0.003" friction="0.0" mu_coulomb="0" mu_viscous="16" />
    </joint>
    <!-- sub-link defining detailed meshes for collision with environment -->
    <link name="right_fr3_link3">
        <visual>
            <geometry>
                <mesh filename="package://franka_description/meshes/visual/link3.dae" />
            </geometry>
        </visual>
        <collision>
            <geometry>
                <mesh filename="package://franka_description/meshes/collision/link3.stl" />
            </geometry>
        </collision>
        <inertial>
            <mass value="0.1" />
            <origin xyz="0 0 0" rpy="0 0 0" />
            <inertia ixx="0.03" iyy="0.03" izz="0.03" ixy="0.0" ixz="0.0" iyz="0.0" />
        </inertial>
    </link>
    <!-- sub-link defining coarse geometries of real robot's internal self-collision -->
    <link name="right_fr3_link3_sc">
        <collision>
            <origin rpy="0 0 0" xyz="0 0 -0.145" />
            <geometry>
                <cylinder length="0.15" radius="0.06" />
            </geometry>
        </collision>
        <collision>
            <origin xyz="0 0 -0.06999999999999999" />
            <geometry>
                <sphere radius="0.06" />
            </geometry>
        </collision>
        <collision>
            <origin xyz="0 0 -0.21999999999999997" />
            <geometry>
                <sphere radius="0.06" />
            </geometry>
        </collision>
        <inertial>
            <mass value="0.1" />
            <origin xyz="0 0 0" rpy="0 0 0" />
            <inertia ixx="0.03" iyy="0.03" izz="0.03" ixy="0.0" ixz="0.0" iyz="0.0" />
        </inertial>
    </link>
    <!-- fixed joint between both sub-links -->
    <joint name="right_fr3_link3_sc_joint" type="fixed">
        <origin rpy="0 0 0" />
        <parent link="right_fr3_link3" />
        <child link="right_fr3_link3_sc" />
    </joint>
    <joint name="right_fr3_joint3" type="revolute">
        <origin rpy="1.5707963267948966 0 0" xyz="0 -0.316 0" />
        <parent link="right_fr3_link2" />
        <child link="right_fr3_link3" />
        <axis xyz="0 0 1" />
        <limit effort="87.0" lower="-2.4937" upper="2.4937" velocity="1.5" />
        <safety_controller k_position="100.0" k_velocity="40.0" soft_lower_limit="-2.4937" soft_upper_limit="2.4937" />
        <dynamics D="1" K="7000" damping="0.003" friction="0.0" mu_coulomb="0" mu_viscous="16" />
    </joint>
    <!-- sub-link defining detailed meshes for collision with environment -->
    <link name="right_fr3_link4">
        <visual>
            <geometry>
                <mesh filename="package://franka_description/meshes/visual/link4.dae" />
            </geometry>
        </visual>
        <collision>
            <geometry>
                <mesh filename="package://franka_description/meshes/collision/link4.stl" />
            </geometry>
        </collision>
        <inertial>
            <mass value="0.1" />
            <origin xyz="0 0 0" rpy="0 0 0" />
            <inertia ixx="0.03" iyy="0.03" izz="0.03" ixy="0.0" ixz="0.0" iyz="0.0" />
        </inertial>
    </link>
    <!-- sub-link defining coarse geometries of real robot's internal self-collision -->
    <link name="right_fr3_link4_sc">
        <collision>
            <origin rpy="0 0 0" xyz="0 0 0" />
            <geometry>
                <cylinder length="0.12" radius="0.06" />
            </geometry>
        </collision>
        <collision>
            <origin xyz="0 0 0.06" />
            <geometry>
                <sphere radius="0.06" />
            </geometry>
        </collision>
        <collision>
            <origin xyz="0 0 -0.06" />
            <geometry>
                <sphere radius="0.06" />
            </geometry>
        </collision>
        <inertial>
            <mass value="0.1" />
            <origin xyz="0 0 0" rpy="0 0 0" />
            <inertia ixx="0.03" iyy="0.03" izz="0.03" ixy="0.0" ixz="0.0" iyz="0.0" />
        </inertial>
    </link>
    <!-- fixed joint between both sub-links -->
    <joint name="right_fr3_link4_sc_joint" type="fixed">
        <origin rpy="0 0 0" />
        <parent link="right_fr3_link4" />
        <child link="right_fr3_link4_sc" />
    </joint>
    <joint name="right_fr3_joint4" type="revolute">
        <origin rpy="1.5707963267948966 0 0" xyz="0.0825 0 0" />
        <parent link="right_fr3_link3" />
        <child link="right_fr3_link4" />
        <axis xyz="0 0 1" />
        <limit effort="87.0" lower="-2.7478" upper="-0.4461" velocity="1.25" />
        <safety_controller k_position="100.0" k_velocity="40.0" soft_lower_limit="-2.7478" soft_upper_limit="-0.4461" />
        <dynamics D="1" K="7000" damping="0.003" friction="0.0" mu_coulomb="0" mu_viscous="16" />
    </joint>
    <!-- sub-link defining detailed meshes for collision with environment -->
    <link name="right_fr3_link5">
        <visual>
            <geometry>
                <mesh filename="package://franka_description/meshes/visual/link5.dae" />
            </geometry>
        </visual>
        <collision>
            <geometry>
                <mesh filename="package://franka_description/meshes/collision/link5.stl" />
            </geometry>
        </collision>
        <inertial>
            <mass value="0.1" />
            <origin xyz="0 0 0" rpy="0 0 0" />
            <inertia ixx="0.03" iyy="0.03" izz="0.03" ixy="0.0" ixz="0.0" iyz="0.0" />
        </inertial>
    </link>
    <!-- sub-link defining coarse geometries of real robot's internal self-collision -->
    <link name="right_fr3_link5_sc">
        <collision>
            <origin rpy="0 0 0" xyz="0 0 -0.26" />
            <geometry>
                <cylinder length="0.1" radius="0.06" />
            </geometry>
        </collision>
        <collision>
            <origin xyz="0 0 -0.21000000000000002" />
            <geometry>
                <sphere radius="0.06" />
            </geometry>
        </collision>
        <collision>
            <origin xyz="0 0 -0.31" />
            <geometry>
                <sphere radius="0.06" />
            </geometry>
        </collision>
        <collision>
            <origin rpy="0 0 0.08" xyz="0 0.08 -0.13" />
            <geometry>
                <cylinder length="0.14" radius="0.025" />
            </geometry>
        </collision>
        <collision>
            <origin xyz="0 0.08 -0.06" />
            <geometry>
                <sphere radius="0.025" />
            </geometry>
        </collision>
        <collision>
            <origin xyz="0 0.08 -0.2" />
            <geometry>
                <sphere radius="0.025" />
            </geometry>
        </collision>
        <inertial>
            <mass value="0.1" />
            <origin xyz="0 0 0" rpy="0 0 0" />
            <inertia ixx="0.03" iyy="0.03" izz="0.03" ixy="0.0" ixz="0.0" iyz="0.0" />
        </inertial>
    </link>
    <!-- fixed joint between both sub-links -->
    <joint name="right_fr3_link5_sc_joint" type="fixed">
        <origin rpy="0 0 0" />
        <parent link="right_fr3_link5" />
        <child link="right_fr3_link5_sc" />
    </joint>
    <joint name="right_fr3_joint5" type="revolute">
        <origin rpy="-1.5707963267948966 0 0" xyz="-0.0825 0.384 0" />
        <parent link="right_fr3_link4" />
        <child link="right_fr3_link5" />
        <axis xyz="0 0 1" />
        <limit effort="12.0" lower="-2.48" upper="2.48" velocity="3.0" />
        <safety_controller k_position="100.0" k_velocity="40.0" soft_lower_limit="-2.48" soft_upper_limit="2.48" />
        <dynamics D="1" K="7000" damping="0.003" friction="0.0" mu_coulomb="0" mu_viscous="16" />
    </joint>
    <!-- sub-link defining detailed meshes for collision with environment -->
    <link name="right_fr3_link6">
        <visual>
            <geometry>
                <mesh filename="package://franka_description/meshes/visual/link6.dae" />
            </geometry>
        </visual>
        <collision>
            <geometry>
                <mesh filename="package://franka_description/meshes/collision/link6.stl" />
            </geometry>
        </collision>
        <inertial>
            <mass value="0.1" />
            <origin xyz="0 0 0" rpy="0 0 0" />
            <inertia ixx="0.03" iyy="0.03" izz="0.03" ixy="0.0" ixz="0.0" iyz="0.0" />
        </inertial>
    </link>
    <!-- sub-link defining coarse geometries of real robot's internal self-collision -->
    <link name="right_fr3_link6_sc">
        <collision>
            <origin rpy="0 0 0" xyz="0 0 -0.03" />
            <geometry>
                <cylinder length="0.08" radius="0.05" />
            </geometry>
        </collision>
        <collision>
            <origin xyz="0 0 0.010000000000000002" />
            <geometry>
                <sphere radius="0.05" />
            </geometry>
        </collision>
        <collision>
            <origin xyz="0 0 -0.07" />
            <geometry>
                <sphere radius="0.05" />
            </geometry>
        </collision>
        <inertial>
            <mass value="0.1" />
            <origin xyz="0 0 0" rpy="0 0 0" />
            <inertia ixx="0.03" iyy="0.03" izz="0.03" ixy="0.0" ixz="0.0" iyz="0.0" />
        </inertial>
    </link>
    <!-- fixed joint between both sub-links -->
    <joint name="right_fr3_link6_sc_joint" type="fixed">
        <origin rpy="0 0 0" />
        <parent link="right_fr3_link6" />
        <child link="right_fr3_link6_sc" />
    </joint>
    <joint name="right_fr3_joint6" type="revolute">
        <origin rpy="1.5707963267948966 0 0" xyz="0 0 0" />
        <parent link="right_fr3_link5" />
        <child link="right_fr3_link6" />
        <axis xyz="0 0 1" />
        <limit effort="12.0" lower="0.8521" upper="4.2094" velocity="1.5" />
        <safety_controller k_position="100.0" k_velocity="40.0" soft_lower_limit="0.8521" soft_upper_limit="4.2094" />
        <dynamics D="1" K="7000" damping="0.003" friction="0.0" mu_coulomb="0" mu_viscous="16" />
    </joint>
    <!-- sub-link defining detailed meshes for collision with environment -->
    <link name="right_fr3_link7">
        <visual>
            <geometry>
                <mesh filename="package://franka_description/meshes/visual/link7.dae" />
            </geometry>
        </visual>
        <collision>
            <geometry>
                <mesh filename="package://franka_description/meshes/collision/link7.stl" />
            </geometry>
        </collision>
        <inertial>
            <mass value="0.1" />
            <origin xyz="0 0 0" rpy="0 0 0" />
            <inertia ixx="0.03" iyy="0.03" izz="0.03" ixy="0.0" ixz="0.0" iyz="0.0" />
        </inertial>
    </link>
    <!-- sub-link defining coarse geometries of real robot's internal self-collision -->
    <link name="right_fr3_link7_sc">
        <collision>
            <origin rpy="0 0 0" xyz="0 0 0.01" />
            <geometry>
                <cylinder length="0.14" radius="0.04" />
            </geometry>
        </collision>
        <collision>
            <origin xyz="0 0 0.08" />
            <geometry>
                <sphere radius="0.04" />
            </geometry>
        </collision>
        <collision>
            <origin xyz="0 0 -0.060000000000000005" />
            <geometry>
                <sphere radius="0.04" />
            </geometry>
        </collision>
        <collision>
            <origin rpy="0 1.5707963267948966 0" xyz="0.06 0 0.082" />
            <geometry>
                <cylinder length="0.01" radius="0.03" />
            </geometry>
        </collision>
        <collision>
            <origin xyz="0.065 0 0.082" />
            <geometry>
                <sphere radius="0.03" />
            </geometry>
        </collision>
        <collision>
            <origin xyz="0.055 0 0.082" />
            <geometry>
                <sphere radius="0.03" />
            </geometry>
        </collision>
        <inertial>
            <mass value="0.1" />
            <origin xyz="0 0 0" rpy="0 0 0" />
            <inertia ixx="0.03" iyy="0.03" izz="0.03" ixy="0.0" ixz="0.0" iyz="0.0" />
        </inertial>
    </link>
    <!-- fixed joint between both sub-links -->
    <joint name="right_fr3_link7_sc_joint" type="fixed">
        <origin rpy="0 0 0.7853981633974483" />
        <parent link="right_fr3_link7" />
        <child link="right_fr3_link7_sc" />
    </joint>
    <joint name="right_fr3_joint7" type="revolute">
        <origin rpy="1.5707963267948966 0 0" xyz="0.088 0 0" />
        <parent link="right_fr3_link6" />
        <child link="right_fr3_link7" />
        <axis xyz="0 0 1" />
        <limit effort="12.0" lower="-2.6895" upper="2.6895" velocity="3.0" />
        <safety_controller k_position="100.0" k_velocity="40.0" soft_lower_limit="-2.6895" soft_upper_limit="2.6895" />
        <dynamics D="1" K="7000" damping="0.003" friction="0.0" mu_coulomb="0" mu_viscous="16" />
    </joint>
    <link name="right_fr3_link8" />
    <joint name="right_fr3_joint8" type="fixed">
        <origin rpy="0 0 0" xyz="0 0 0.107" />
        <parent link="right_fr3_link7" />
        <child link="right_fr3_link8" />
    </joint>
    <joint name="right_fr3_hand_joint" type="fixed">
        <parent link="right_fr3_link8" />
        <child link="right_fr3_hand" />
        <origin rpy="0 0 -0.785398163" xyz="0 0 0.002" />
    </joint>
    <!-- sub-link defining detailed meshes for collision with environment -->
    <link name="right_fr3_hand">
        <visual>
            <geometry>
                <mesh filename="package://franka_description/meshes/visual/hand.dae" />
            </geometry>
        </visual>
        <collision>
            <geometry>
                <mesh filename="package://franka_description/meshes/collision/hand.stl" />
            </geometry>
        </collision>
        <inertial>
            <mass value="0.1" />
            <origin xyz="0 0 0" rpy="0 0 0" />
            <inertia ixx="0.03" iyy="0.03" izz="0.03" ixy="0.0" ixz="0.0" iyz="0.0" />
        </inertial>
    </link>
    <!-- sub-link defining coarse geometries of real robot's internal self-collision -->
    <link name="right_fr3_hand_sc">
        <collision>
            <origin rpy="1.5707963267948966 0 0" xyz="0 0 0.04" />
            <geometry>
                <cylinder length="0.1" radius="0.04" />
            </geometry>
        </collision>
        <collision>
            <origin xyz="0 0.05 0.04" />
            <geometry>
                <sphere radius="0.04" />
            </geometry>
        </collision>
        <collision>
            <origin xyz="0 -0.05 0.04" />
            <geometry>
                <sphere radius="0.04" />
            </geometry>
        </collision>
        <collision>
            <origin rpy="1.5707963267948966 0 0" xyz="0 0 0.1" />
            <geometry>
                <cylinder length="0.1" radius="0.02" />
            </geometry>
        </collision>
        <collision>
            <origin xyz="0 0.05 0.1" />
            <geometry>
                <sphere radius="0.02" />
            </geometry>
        </collision>
        <collision>
            <origin xyz="0 -0.05 0.1" />
            <geometry>
                <sphere radius="0.02" />
            </geometry>
        </collision>
        <inertial>
            <mass value="0.1" />
            <origin xyz="0 0 0" rpy="0 0 0" />
            <inertia ixx="0.03" iyy="0.03" izz="0.03" ixy="0.0" ixz="0.0" iyz="0.0" />
        </inertial>
    </link>
    <!-- fixed joint between both sub-links -->
    <joint name="right_fr3_hand_sc_joint" type="fixed">
        <origin rpy="0 0 0" />
        <parent link="right_fr3_hand" />
        <child link="right_fr3_hand_sc" />
    </joint>
    <!-- Define the hand_tcp frame -->
    <link name="right_fr3_hand_tcp" />
    <joint name="right_fr3_hand_tcp_joint" type="fixed">
        <origin rpy="0 0 0" xyz="0 0 0.1034" />
        <parent link="right_fr3_hand" />
        <child link="right_fr3_hand_tcp" />
    </joint>
    <link name="right_fr3_leftfinger">
        <visual>
            <geometry>
                <mesh filename="package://franka_description/meshes/visual/finger.dae" />
            </geometry>
        </visual>
        <!-- screw mount -->
        <collision>
            <origin rpy="0 0 0" xyz="0 18.5e-3 11e-3" />
            <geometry>
                <box size="22e-3 15e-3 20e-3" />
            </geometry>
        </collision>
        <!-- cartriage sledge -->
        <collision>
            <origin rpy="0 0 0" xyz="0 6.8e-3 2.2e-3" />
            <geometry>
                <box size="22e-3 8.8e-3 3.8e-3" />
            </geometry>
        </collision>
        <!-- diagonal finger -->
        <collision>
            <origin rpy="0.5235987755982988 0 0" xyz="0 15.9e-3 28.35e-3" />
            <geometry>
                <box size="17.5e-3 7e-3 23.5e-3" />
            </geometry>
        </collision>
        <!-- rubber tip with which to grasp -->
        <collision>
            <origin rpy="0 0 0" xyz="0 7.58e-3 45.25e-3" />
            <geometry>
                <box size="17.5e-3 15.2e-3 18.5e-3" />
            </geometry>
        </collision>
        <inertial>
            <mass value="0.1" />
            <origin xyz="0 0 0" rpy="0 0 0" />
            <inertia ixx="0.03" iyy="0.03" izz="0.03" ixy="0.0" ixz="0.0" iyz="0.0" />
        </inertial>
    </link>
    <link name="right_fr3_rightfinger">
        <visual>
            <origin rpy="0 0 3.141592653589793" xyz="0 0 0" />
            <geometry>
                <mesh filename="package://franka_description/meshes/visual/finger.dae" />
            </geometry>
        </visual>
        <!-- screw mount -->
        <collision>
            <origin rpy="0 0 0" xyz="0 -18.5e-3 11e-3" />
            <geometry>
                <box size="22e-3 15e-3 20e-3" />
            </geometry>
        </collision>
        <!-- cartriage sledge -->
        <collision>
            <origin rpy="0 0 0" xyz="0 -6.8e-3 2.2e-3" />
            <geometry>
                <box size="22e-3 8.8e-3 3.8e-3" />
            </geometry>
        </collision>
        <!-- diagonal finger -->
        <collision>
            <origin rpy="-0.5235987755982988 0 0" xyz="0 -15.9e-3 28.35e-3" />
            <geometry>
                <box size="17.5e-3 7e-3 23.5e-3" />
            </geometry>
        </collision>
        <!-- rubber tip with which to grasp -->
        <collision>
            <origin rpy="0 0 0" xyz="0 -7.58e-3 45.25e-3" />
            <geometry>
                <box size="17.5e-3 15.2e-3 18.5e-3" />
            </geometry>
        </collision>
        <inertial>
            <mass value="0.1" />
            <origin xyz="0 0 0" rpy="0 0 0" />
            <inertia ixx="0.03" iyy="0.03" izz="0.03" ixy="0.0" ixz="0.0" iyz="0.0" />
        </inertial>
    </link>
    <joint name="right_fr3_finger_joint1" type="prismatic">
        <parent link="right_fr3_hand" />
        <child link="right_fr3_leftfinger" />
        <origin rpy="0 0 0" xyz="0 0 0.0584" />
        <axis xyz="0 1 0" />
        <limit effort="100" lower="0.0" upper="0.04" velocity="0.2" />
        <dynamics damping="0.3" />
    </joint>
    <joint name="right_fr3_finger_joint2" type="prismatic">
        <parent link="right_fr3_hand" />
        <child link="right_fr3_rightfinger" />
        <origin rpy="0 0 0" xyz="0 0 0.0584" />
        <axis xyz="0 -1 0" />
        <limit effort="100" lower="0.0" upper="0.04" velocity="0.2" />
        <mimic joint="right_fr3_finger_joint1" />
        <dynamics damping="0.3" />
    </joint>
    <link name="right_camera_bracket">
        <inertial>
            <origin rpy="0 0 0" xyz="0.0134438110340833 -0.168362228593174 0.448374390946475" />
            <mass value="17.8" />
            <inertia ixx="6.25233742851433" ixy="-0.52125829292522" ixz="-0.826110619533779" iyy="4.1685965211151" iyz="0.217129723015581" izz="5.22932283924632" />
        </inertial>
        <visual>
            <origin rpy="0 0 0" xyz="0 0 0" />
            <geometry>
                <mesh filename="package://mr1000_dual_fr3_description/meshes/camera_bracket.STL" />
            </geometry>
            <material name="">
                <color rgba="0.898039215686275 0.917647058823529 0.929411764705882 1" />
            </material>
        </visual>
        <collision>
            <origin rpy="0 0 0" xyz="0 0 0" />
            <geometry>
                <mesh filename="package://mr1000_dual_fr3_description/meshes/camera_bracket.STL" />
            </geometry>
        </collision>
    </link>
    <joint name="right_camera_bracket_joint" type="fixed">
        <origin rpy="0 0 -0.785398163" xyz="0 0 0" />
        <parent link="right_fr3_link8" />
        <child link="right_camera_bracket" />
    </joint>
    <!-- camera body, with origin at bottom screw mount -->
    <joint name="right_camera_joint" type="fixed">
        <origin rpy="3.14159265358979 -1.5707963267949 0" xyz="0.0829950975679638 0 0.01215" />
        <parent link="right_camera_bracket" />
        <child link="right_camera_bottom_screw_frame" />
    </joint>
    <link name="right_camera_bottom_screw_frame" />
    <joint name="right_camera_link_joint" type="fixed">
        <origin rpy="0 0 0" xyz="0.010600000000000002 0.0175 0.0125" />
        <parent link="right_camera_bottom_screw_frame" />
        <child link="right_camera_link" />
    </joint>
    <link name="right_camera_link">
        <visual>
            <!-- the mesh origin is at front plate in between the two infrared camera axes -->
            <origin rpy="1.5707963267948966 0 1.5707963267948966" xyz="0.0043 -0.0175 0" />
            <geometry>
                <mesh filename="package://realsense2_description/meshes/d435.dae" />
            </geometry>
        </visual>
        <collision>
            <origin rpy="0 0 0" xyz="0 -0.0175 0" />
            <geometry>
                <box size="0.02505 0.09 0.025" />
            </geometry>
        </collision>
        <inertial>
            <!-- The following are not reliable values, and should not be used for modeling -->
            <mass value="0.072" />
            <origin xyz="0 0 0" rpy="0 0 0" />
            <inertia ixx="0.003881243" ixy="0.0" ixz="0.0" iyy="0.000498940" iyz="0.0" izz="0.003879257" />
        </inertial>
    </link>
    <!-- camera depth joints and links -->
    <joint name="right_camera_depth_joint" type="fixed">
        <origin rpy="0 0 0" xyz="0 0 0" />
        <parent link="right_camera_link" />
        <child link="right_camera_depth_frame" />
    </joint>
    <link name="right_camera_depth_frame" />
    <joint name="right_camera_depth_optical_joint" type="fixed">
        <origin rpy="-1.5707963267948966 0 -1.5707963267948966" xyz="0 0 0" />
        <parent link="right_camera_depth_frame" />
        <child link="right_camera_depth_optical_frame" />
    </joint>
    <link name="right_camera_depth_optical_frame" />
    <!-- camera left IR joints and links -->
    <joint name="right_camera_infra1_joint" type="fixed">
        <origin rpy="0 0 0" xyz="0 0.0 0" />
        <parent link="right_camera_link" />
        <child link="right_camera_infra1_frame" />
    </joint>
    <link name="right_camera_infra1_frame" />
    <joint name="right_camera_infra1_optical_joint" type="fixed">
        <origin rpy="-1.5707963267948966 0 -1.5707963267948966" xyz="0 0 0" />
        <parent link="right_camera_infra1_frame" />
        <child link="right_camera_infra1_optical_frame" />
    </joint>
    <link name="right_camera_infra1_optical_frame" />
    <!-- camera right IR joints and links -->
    <joint name="right_camera_infra2_joint" type="fixed">
        <origin rpy="0 0 0" xyz="0 -0.05 0" />
        <parent link="right_camera_link" />
        <child link="right_camera_infra2_frame" />
    </joint>
    <link name="right_camera_infra2_frame" />
    <joint name="right_camera_infra2_optical_joint" type="fixed">
        <origin rpy="-1.5707963267948966 0 -1.5707963267948966" xyz="0 0 0" />
        <parent link="right_camera_infra2_frame" />
        <child link="right_camera_infra2_optical_frame" />
    </joint>
    <link name="right_camera_infra2_optical_frame" />
    <!-- camera color joints and links -->
    <joint name="right_camera_color_joint" type="fixed">
        <origin rpy="0 0 0" xyz="0 0.015 0" />
        <parent link="right_camera_link" />
        <child link="right_camera_color_frame" />
    </joint>
    <link name="right_camera_color_frame" />
    <joint name="right_camera_color_optical_joint" type="fixed">
        <origin rpy="-1.5707963267948966 0 -1.5707963267948966" xyz="0 0 0" />
        <parent link="right_camera_color_frame" />
        <child link="right_camera_color_optical_frame" />
    </joint>
    <link name="right_camera_color_optical_frame" />
    <link name="right_camera_accel_frame" />
    <link name="right_camera_accel_optical_frame" />
    <link name="right_camera_gyro_frame" />
    <link name="right_camera_gyro_optical_frame" />
    <joint name="right_camera_accel_joint" type="fixed">
        <origin rpy="0 0 0" xyz="-0.01174 -0.00552 0.0051" />
        <parent link="right_camera_link" />
        <child link="right_camera_accel_frame" />
    </joint>
    <joint name="right_camera_accel_optical_joint" type="fixed">
        <origin rpy="-1.5707963267948966 0 -1.5707963267948966" xyz="0 0 0" />
        <parent link="right_camera_accel_frame" />
        <child link="right_camera_accel_optical_frame" />
    </joint>
    <joint name="right_camera_gyro_joint" type="fixed">
        <origin rpy="0 0 0" xyz="-0.01174 -0.00552 0.0051" />
        <parent link="right_camera_link" />
        <child link="right_camera_gyro_frame" />
    </joint>
    <joint name="right_camera_gyro_optical_joint" type="fixed">
        <origin rpy="-1.5707963267948966 0 -1.5707963267948966" xyz="0 0 0" />
        <parent link="right_camera_gyro_frame" />
        <child link="right_camera_gyro_optical_frame" />
    </joint>
    <transmission name="trans_wheel_LF_joint">
        <type>transmission_interface/SimpleTransmission</type>
        <joint name="wheel_LF_joint">
            <hardwareInterface>hardware_interface/EffortJointInterface</hardwareInterface>
        </joint>
        <actuator name="wheel_LF_joint_motor">
            <hardwareInterface>hardware_interface/EffortJointInterface</hardwareInterface>
            <mechanicalReduction>1</mechanicalReduction>
        </actuator>
    </transmission>
    <transmission name="trans_wheel_LB_joint">
        <type>transmission_interface/SimpleTransmission</type>
        <joint name="wheel_LB_joint">
            <hardwareInterface>hardware_interface/EffortJointInterface</hardwareInterface>
        </joint>
        <actuator name="wheel_LB_joint_motor">
            <hardwareInterface>hardware_interface/EffortJointInterface</hardwareInterface>
            <mechanicalReduction>1</mechanicalReduction>
        </actuator>
    </transmission>
    <transmission name="trans_wheel_RF_joint">
        <type>transmission_interface/SimpleTransmission</type>
        <joint name="wheel_RF_joint">
            <hardwareInterface>hardware_interface/EffortJointInterface</hardwareInterface>
        </joint>
        <actuator name="wheel_RF_joint_motor">
            <hardwareInterface>hardware_interface/EffortJointInterface</hardwareInterface>
            <mechanicalReduction>1</mechanicalReduction>
        </actuator>
    </transmission>
    <transmission name="trans_wheel_RB_joint">
        <type>transmission_interface/SimpleTransmission</type>
        <joint name="wheel_RB_joint">
            <hardwareInterface>hardware_interface/EffortJointInterface</hardwareInterface>
        </joint>
        <actuator name="wheel_RB_joint_motor">
            <hardwareInterface>hardware_interface/EffortJointInterface</hardwareInterface>
            <mechanicalReduction>1</mechanicalReduction>
        </actuator>
    </transmission>
    <transmission name="trans_left_fr3_joint1">
        <type>transmission_interface/SimpleTransmission</type>
        <joint name="left_fr3_joint1">
            <hardwareInterface>hardware_interface/EffortJointInterface</hardwareInterface>
        </joint>
        <actuator name="left_fr3_joint1_motor">
            <hardwareInterface>hardware_interface/EffortJointInterface</hardwareInterface>
            <mechanicalReduction>1</mechanicalReduction>
        </actuator>
    </transmission>
    <transmission name="trans_left_fr3_joint2">
        <type>transmission_interface/SimpleTransmission</type>
        <joint name="left_fr3_joint2">
            <hardwareInterface>hardware_interface/EffortJointInterface</hardwareInterface>
        </joint>
        <actuator name="left_fr3_joint2_motor">
            <hardwareInterface>hardware_interface/EffortJointInterface</hardwareInterface>
            <mechanicalReduction>1</mechanicalReduction>
        </actuator>
    </transmission>
    <transmission name="trans_left_fr3_joint3">
        <type>transmission_interface/SimpleTransmission</type>
        <joint name="left_fr3_joint3">
            <hardwareInterface>hardware_interface/EffortJointInterface</hardwareInterface>
        </joint>
        <actuator name="left_fr3_joint3_motor">
            <hardwareInterface>hardware_interface/EffortJointInterface</hardwareInterface>
            <mechanicalReduction>1</mechanicalReduction>
        </actuator>
    </transmission>
    <transmission name="trans_left_fr3_joint4">
        <type>transmission_interface/SimpleTransmission</type>
        <joint name="left_fr3_joint4">
            <hardwareInterface>hardware_interface/EffortJointInterface</hardwareInterface>
        </joint>
        <actuator name="left_fr3_joint4_motor">
            <hardwareInterface>hardware_interface/EffortJointInterface</hardwareInterface>
            <mechanicalReduction>1</mechanicalReduction>
        </actuator>
    </transmission>
    <transmission name="trans_left_fr3_joint5">
        <type>transmission_interface/SimpleTransmission</type>
        <joint name="left_fr3_joint5">
            <hardwareInterface>hardware_interface/EffortJointInterface</hardwareInterface>
        </joint>
        <actuator name="left_fr3_joint5_motor">
            <hardwareInterface>hardware_interface/EffortJointInterface</hardwareInterface>
            <mechanicalReduction>1</mechanicalReduction>
        </actuator>
    </transmission>
    <transmission name="trans_left_fr3_joint6">
        <type>transmission_interface/SimpleTransmission</type>
        <joint name="left_fr3_joint6">
            <hardwareInterface>hardware_interface/EffortJointInterface</hardwareInterface>
        </joint>
        <actuator name="left_fr3_joint6_motor">
            <hardwareInterface>hardware_interface/EffortJointInterface</hardwareInterface>
            <mechanicalReduction>1</mechanicalReduction>
        </actuator>
    </transmission>
    <transmission name="trans_left_fr3_joint7">
        <type>transmission_interface/SimpleTransmission</type>
        <joint name="left_fr3_joint7">
            <hardwareInterface>hardware_interface/EffortJointInterface</hardwareInterface>
        </joint>
        <actuator name="left_fr3_joint7_motor">
            <hardwareInterface>hardware_interface/EffortJointInterface</hardwareInterface>
            <mechanicalReduction>1</mechanicalReduction>
        </actuator>
    </transmission>
    <transmission name="trans_left_fr3_finger_joint1">
        <type>transmission_interface/SimpleTransmission</type>
        <joint name="left_fr3_finger_joint1">
            <hardwareInterface>hardware_interface/EffortJointInterface</hardwareInterface>
        </joint>
        <actuator name="left_fr3_finger_joint1_motor">
            <hardwareInterface>hardware_interface/EffortJointInterface</hardwareInterface>
            <mechanicalReduction>1</mechanicalReduction>
        </actuator>
    </transmission>
    <transmission name="trans_left_fr3_finger_joint2">
        <type>transmission_interface/SimpleTransmission</type>
        <joint name="left_fr3_finger_joint2">
            <hardwareInterface>hardware_interface/EffortJointInterface</hardwareInterface>
        </joint>
        <actuator name="left_fr3_finger_joint2_motor">
            <hardwareInterface>hardware_interface/EffortJointInterface</hardwareInterface>
            <mechanicalReduction>1</mechanicalReduction>
        </actuator>
    </transmission>
    <transmission name="trans_right_fr3_joint1">
        <type>transmission_interface/SimpleTransmission</type>
        <joint name="right_fr3_joint1">
            <hardwareInterface>hardware_interface/EffortJointInterface</hardwareInterface>
        </joint>
        <actuator name="right_fr3_joint1_motor">
            <hardwareInterface>hardware_interface/EffortJointInterface</hardwareInterface>
            <mechanicalReduction>1</mechanicalReduction>
        </actuator>
    </transmission>
    <transmission name="trans_right_fr3_joint2">
        <type>transmission_interface/SimpleTransmission</type>
        <joint name="right_fr3_joint2">
            <hardwareInterface>hardware_interface/EffortJointInterface</hardwareInterface>
        </joint>
        <actuator name="right_fr3_joint2_motor">
            <hardwareInterface>hardware_interface/EffortJointInterface</hardwareInterface>
            <mechanicalReduction>1</mechanicalReduction>
        </actuator>
    </transmission>
    <transmission name="trans_right_fr3_joint3">
        <type>transmission_interface/SimpleTransmission</type>
        <joint name="right_fr3_joint3">
            <hardwareInterface>hardware_interface/EffortJointInterface</hardwareInterface>
        </joint>
        <actuator name="right_fr3_joint3_motor">
            <hardwareInterface>hardware_interface/EffortJointInterface</hardwareInterface>
            <mechanicalReduction>1</mechanicalReduction>
        </actuator>
    </transmission>
    <transmission name="trans_right_fr3_joint4">
        <type>transmission_interface/SimpleTransmission</type>
        <joint name="right_fr3_joint4">
            <hardwareInterface>hardware_interface/EffortJointInterface</hardwareInterface>
        </joint>
        <actuator name="right_fr3_joint4_motor">
            <hardwareInterface>hardware_interface/EffortJointInterface</hardwareInterface>
            <mechanicalReduction>1</mechanicalReduction>
        </actuator>
    </transmission>
    <transmission name="trans_right_fr3_joint5">
        <type>transmission_interface/SimpleTransmission</type>
        <joint name="right_fr3_joint5">
            <hardwareInterface>hardware_interface/EffortJointInterface</hardwareInterface>
        </joint>
        <actuator name="right_fr3_joint5_motor">
            <hardwareInterface>hardware_interface/EffortJointInterface</hardwareInterface>
            <mechanicalReduction>1</mechanicalReduction>
        </actuator>
    </transmission>
    <transmission name="trans_right_fr3_joint6">
        <type>transmission_interface/SimpleTransmission</type>
        <joint name="right_fr3_joint6">
            <hardwareInterface>hardware_interface/EffortJointInterface</hardwareInterface>
        </joint>
        <actuator name="right_fr3_joint6_motor">
            <hardwareInterface>hardware_interface/EffortJointInterface</hardwareInterface>
            <mechanicalReduction>1</mechanicalReduction>
        </actuator>
    </transmission>
    <transmission name="trans_right_fr3_joint7">
        <type>transmission_interface/SimpleTransmission</type>
        <joint name="right_fr3_joint7">
            <hardwareInterface>hardware_interface/EffortJointInterface</hardwareInterface>
        </joint>
        <actuator name="right_fr3_joint7_motor">
            <hardwareInterface>hardware_interface/EffortJointInterface</hardwareInterface>
            <mechanicalReduction>1</mechanicalReduction>
        </actuator>
    </transmission>
    <transmission name="trans_right_fr3_finger_joint1">
        <type>transmission_interface/SimpleTransmission</type>
        <joint name="right_fr3_finger_joint1">
            <hardwareInterface>hardware_interface/EffortJointInterface</hardwareInterface>
        </joint>
        <actuator name="right_fr3_finger_joint1_motor">
            <hardwareInterface>hardware_interface/EffortJointInterface</hardwareInterface>
            <mechanicalReduction>1</mechanicalReduction>
        </actuator>
    </transmission>
    <transmission name="trans_right_fr3_finger_joint2">
        <type>transmission_interface/SimpleTransmission</type>
        <joint name="right_fr3_finger_joint2">
            <hardwareInterface>hardware_interface/EffortJointInterface</hardwareInterface>
        </joint>
        <actuator name="right_fr3_finger_joint2_motor">
            <hardwareInterface>hardware_interface/EffortJointInterface</hardwareInterface>
            <mechanicalReduction>1</mechanicalReduction>
        </actuator>
    </transmission>
    <gazebo>
        <plugin name="gazebo_ros_control" filename="libgazebo_ros_control.so">
            <robotNamespace>/</robotNamespace>
        </plugin>
    </gazebo>
</robot>

