<?xml version="1.0" ?>
<!-- =================================================================================== -->
<!-- |    This document was autogenerated by xacro from /home/rpp/rpp_ws/src/robot/mmx5_description/xacro/mmx5/robot.xacro | -->
<!-- |    EDITING THIS FILE BY HAND IS NOT RECOMMENDED                                 | -->
<!-- =================================================================================== -->
<robot name="mr1000">
    <!-- <xacro:macro name="RS-16"
        params=" name:=robosense topic:=/robosense_points hz:=20 lasers:=16 samples:=900
    collision_range:=0.4 min_range:=0.4 max_range:=150.0 noise:=0.008 min_angle:=-${PI}
    max_angle:=${PI} gpu:=false">
        <gazebo reference="${namespace}${name}">
            <material>Gazebo/Black</material>
        </gazebo>
    </xacro:macro> -->
    <link name="base_link">
        <visual>
            <origin rpy="0 0 0" xyz="0 0 0" />
            <geometry>
                <!--Themass of the particle is distributed at a point-->
                <sphere radius="0.00001" />
            </geometry>
            <material name="yellow">
                <color rgba="1 0.4 0 1" />
            </material>
        </visual>
    </link>
    <link name="trunk_link">
        <inertial>
            <origin rpy="0 0 0" xyz="-0.0118811326799766 -6.44860879235185E-06 0.062245748982637" />
            <mass value="47.4583095761037" />
            <inertia ixx="0.623532452496942" ixy="5.13756351720321E-05" ixz="-0.000299376267147842" iyy="1.05606469859637" iyz="-2.64900697486282E-05" izz="1.58154213718717" />
        </inertial>
        <visual>
            <origin rpy="0 0 0" xyz="0 0 0" />
            <geometry>
                <mesh filename="package://mmx5_description/meshes/mr1000/trunk_link.STL" />
            </geometry>
            <material name="yellow">
                <color rgba="0.752941176470588 0.752941176470588 0.752941176470588 1" />
            </material>
        </visual>
        <collision>
            <origin rpy="0 0 0" xyz="0 0 0" />
            <geometry>
                <mesh filename="package://mmx5_description/meshes/mr1000/trunk_link.STL" />
            </geometry>
        </collision>
    </link>
    <!-- Define a fixed joint virtual base_link and the car's real chassis trunk_link, base_link is
  in the middle of trunk_link -->
    <joint name="dummy_joint" type="fixed">
        <origin rpy=" 0 0 0" xyz=" 0 0 0  " />
        <parent link="base_link" />
        <child link="trunk_link" />
    </joint>
    <link name="wheel_FL_link">
        <inertial>
            <origin rpy="0 0 0" xyz="-3.50822611239199E-08 -0.00432439648807853 1.13223465993822E-06" />
            <mass value="3.16341062169741" />
            <inertia ixx="0.0251239439066133" ixy="-1.30692678631824E-07" ixz="-1.94955257575282E-07" iyy="0.0482525004035813" iyz="-1.37572420061042E-07" izz="0.0251242609803983" />
        </inertial>
        <visual>
            <origin rpy="0 0 0" xyz="0 0 0" />
            <geometry>
                <mesh filename="package://mmx5_description/meshes/mr1000/wheel.STL" />
            </geometry>
            <material name="">
                <color rgba="0.941176470588235 0.674509803921569 0.117647058823529 1" />
            </material>
        </visual>
        <collision>
            <origin rpy="1.5707963267948966 0 0" xyz="0 0 0" />
            <geometry>
                <cylinder length="0.078" radius="0.1575" />
            </geometry>
        </collision>
    </link>
    <joint name="wheel_FL_joint" type="continuous">
        <parent link="base_link" />
        <child link="wheel_FL_link" />
        <origin rpy="0 0 0" xyz="0.2122 0.3135 -1.3877787807814457e-17" />
        <axis rpy="0 0 0" xyz="0 1 0" />
    </joint>
    <gazebo reference="wheel_FL_link">
        <!-- 摩擦系数（橡胶轮胎典型值） -->
        <mu1 value="1.2" />
        <mu2 value="1.0" />
        <!-- 接触刚度与阻尼 -->
        <kp value="10000000.0" />
        <kd value="1000.0" />
        <!-- 旋转方向 -->
        <fdir1 value="1 0 0" />
        <!-- 材质 -->
        <material>Gazebo/Black</material>
        <plugin name="gazebo_ros_control" filename="libgazebo_ros_control.so">
            <robotNamespace>/</robotNamespace>
        </plugin>
    </gazebo>
    <transmission name="wheel_FL_trans">
        <type>transmission_interface/SimpleTransmission</type>
        <actuator name="wheel_FL_motor">
            <mechanicalReduction>1</mechanicalReduction>
            <hardwareInterface>hardware_interface/EffortJointInterface</hardwareInterface>
        </actuator>
        <joint name="wheel_FL_joint">
            <hardwareInterface>VelocityJointInterface</hardwareInterface>
        </joint>
    </transmission>
    <link name="wheel_FR_link">
        <inertial>
            <origin rpy="0 0 0" xyz="-3.50822611239199E-08 -0.00432439648807853 1.13223465993822E-06" />
            <mass value="3.16341062169741" />
            <inertia ixx="0.0251239439066133" ixy="-1.30692678631824E-07" ixz="-1.94955257575282E-07" iyy="0.0482525004035813" iyz="-1.37572420061042E-07" izz="0.0251242609803983" />
        </inertial>
        <visual>
            <origin rpy="3.141592653589793 0 0" xyz="0 0 0" />
            <geometry>
                <mesh filename="package://mmx5_description/meshes/mr1000/wheel.STL" />
            </geometry>
            <material name="">
                <color rgba="0.941176470588235 0.674509803921569 0.117647058823529 1" />
            </material>
        </visual>
        <collision>
            <origin rpy="1.5707963267948966 0 0" xyz="0 0 0" />
            <geometry>
                <cylinder length="0.078" radius="0.1575" />
            </geometry>
        </collision>
    </link>
    <joint name="wheel_FR_joint" type="continuous">
        <parent link="base_link" />
        <child link="wheel_FR_link" />
        <origin rpy="0 0 0" xyz="0.2122 -0.3135 -1.3877787807814457e-17" />
        <axis rpy="0 0 0" xyz="0 1 0" />
    </joint>
    <gazebo reference="wheel_FR_link">
        <!-- 摩擦系数（橡胶轮胎典型值） -->
        <mu1 value="1.2" />
        <mu2 value="1.0" />
        <!-- 接触刚度与阻尼 -->
        <kp value="10000000.0" />
        <kd value="1000.0" />
        <!-- 旋转方向 -->
        <fdir1 value="1 0 0" />
        <!-- 材质 -->
        <material>Gazebo/Black</material>
    </gazebo>
    <transmission name="wheel_FR_trans">
        <type>transmission_interface/SimpleTransmission</type>
        <actuator name="wheel_FR_motor">
            <mechanicalReduction>1</mechanicalReduction>
            <hardwareInterface>hardware_interface/EffortJointInterface</hardwareInterface>
        </actuator>
        <joint name="wheel_FR_joint">
            <hardwareInterface>VelocityJointInterface</hardwareInterface>
        </joint>
    </transmission>
    <link name="wheel_RL_link">
        <inertial>
            <origin rpy="0 0 0" xyz="-3.50822611239199E-08 -0.00432439648807853 1.13223465993822E-06" />
            <mass value="3.16341062169741" />
            <inertia ixx="0.0251239439066133" ixy="-1.30692678631824E-07" ixz="-1.94955257575282E-07" iyy="0.0482525004035813" iyz="-1.37572420061042E-07" izz="0.0251242609803983" />
        </inertial>
        <visual>
            <origin rpy="0 0 0" xyz="0 0 0" />
            <geometry>
                <mesh filename="package://mmx5_description/meshes/mr1000/wheel.STL" />
            </geometry>
            <material name="">
                <color rgba="0.941176470588235 0.674509803921569 0.117647058823529 1" />
            </material>
        </visual>
        <collision>
            <origin rpy="1.5707963267948966 0 0" xyz="0 0 0" />
            <geometry>
                <cylinder length="0.078" radius="0.1575" />
            </geometry>
        </collision>
    </link>
    <joint name="wheel_RL_joint" type="continuous">
        <parent link="base_link" />
        <child link="wheel_RL_link" />
        <origin rpy="0 0 0" xyz="-0.2122 0.3135 -1.3877787807814457e-17" />
        <axis rpy="0 0 0" xyz="0 1 0" />
    </joint>
    <gazebo reference="wheel_RL_link">
        <!-- 摩擦系数（橡胶轮胎典型值） -->
        <mu1 value="1.2" />
        <mu2 value="1.0" />
        <!-- 接触刚度与阻尼 -->
        <kp value="10000000.0" />
        <kd value="1000.0" />
        <!-- 旋转方向 -->
        <fdir1 value="1 0 0" />
        <!-- 材质 -->
        <material>Gazebo/Black</material>
    </gazebo>
    <transmission name="wheel_RL_trans">
        <type>transmission_interface/SimpleTransmission</type>
        <actuator name="wheel_RL_motor">
            <mechanicalReduction>1</mechanicalReduction>
            <hardwareInterface>hardware_interface/EffortJointInterface</hardwareInterface>
        </actuator>
        <joint name="wheel_RL_joint">
            <hardwareInterface>VelocityJointInterface</hardwareInterface>
        </joint>
    </transmission>
    <link name="wheel_RR_link">
        <inertial>
            <origin rpy="0 0 0" xyz="-3.50822611239199E-08 -0.00432439648807853 1.13223465993822E-06" />
            <mass value="3.16341062169741" />
            <inertia ixx="0.0251239439066133" ixy="-1.30692678631824E-07" ixz="-1.94955257575282E-07" iyy="0.0482525004035813" iyz="-1.37572420061042E-07" izz="0.0251242609803983" />
        </inertial>
        <visual>
            <origin rpy="3.141592653589793 0 0" xyz="0 0 0" />
            <geometry>
                <mesh filename="package://mmx5_description/meshes/mr1000/wheel.STL" />
            </geometry>
            <material name="">
                <color rgba="0.941176470588235 0.674509803921569 0.117647058823529 1" />
            </material>
        </visual>
        <collision>
            <origin rpy="1.5707963267948966 0 0" xyz="0 0 0" />
            <geometry>
                <cylinder length="0.078" radius="0.1575" />
            </geometry>
        </collision>
    </link>
    <joint name="wheel_RR_joint" type="continuous">
        <parent link="base_link" />
        <child link="wheel_RR_link" />
        <origin rpy="0 0 0" xyz="-0.2122 -0.3135 -1.3877787807814457e-17" />
        <axis rpy="0 0 0" xyz="0 1 0" />
    </joint>
    <gazebo reference="wheel_RR_link">
        <!-- 摩擦系数（橡胶轮胎典型值） -->
        <mu1 value="1.2" />
        <mu2 value="1.0" />
        <!-- 接触刚度与阻尼 -->
        <kp value="10000000.0" />
        <kd value="1000.0" />
        <!-- 旋转方向 -->
        <fdir1 value="1 0 0" />
        <!-- 材质 -->
        <material>Gazebo/Black</material>
    </gazebo>
    <transmission name="wheel_RR_trans">
        <type>transmission_interface/SimpleTransmission</type>
        <actuator name="wheel_RR_motor">
            <mechanicalReduction>1</mechanicalReduction>
            <hardwareInterface>hardware_interface/EffortJointInterface</hardwareInterface>
        </actuator>
        <joint name="wheel_RR_joint">
            <hardwareInterface>VelocityJointInterface</hardwareInterface>
        </joint>
    </transmission>
    <gazebo>
        <plugin filename="libgazebo_ros_control.so" name="gazebo_ros_control">
            <robotNamespace />
            <robotSimType>gazebo_ros_control/DefaultRobotHWSim</robotSimType>
            <legacyModeNS>true</legacyModeNS>
            <pid>
                <joint name="wheel_FL_joint">
                    <p>1000</p>
                    <i>0</i>
                    <d>0</d>
                </joint>
                <joint name="wheel_FR_joint">
                    <p>1000</p>
                    <i>0</i>
                    <d>0</d>
                </joint>
                <joint name="wheel_RL_joint">
                    <p>1000</p>
                    <i>0</i>
                    <d>0</d>
                </joint>
                <joint name="wheel_RR_joint">
                    <p>1000</p>
                    <i>0</i>
                    <d>0</d>
                </joint>
            </pid>
        </plugin>
    </gazebo>
    <link name="nav_link">
        <inertial>
            <origin rpy="0 0 0" xyz="-0.0727566003532676 -0.00175742740530046 0.157922172831195" />
            <mass value="17.2208304717184" />
            <inertia ixx="0.384702857034932" ixy="-0.000625632545270021" ixz="-0.00691279028613271" iyy="0.166505130785033" iyz="-4.42348202845755E-05" izz="0.470998373406889" />
        </inertial>
        <visual>
            <origin rpy="0 0 0" xyz="-0.01 0 0" />
            <geometry>
                <mesh filename="package://mmx5_description/meshes/navigation_kit/trunk_nav_Link.STL" />
            </geometry>
            <material name="">
                <color rgba="0.752941176470588 0.752941176470588 0.752941176470588 1" />
            </material>
        </visual>
        <collision>
            <origin rpy="0 0 0" xyz="-0.083 0 0" />
            <geometry>
                <mesh filename="package://mmx5_description/meshes/navigation_kit/trunk_nav_Link_sc.STL" />
            </geometry>
        </collision>
    </link>
    <joint name="nav_joint" type="fixed">
        <origin rpy="0 0 0" xyz="-0.0229999999999998 0 0.1895" />
        <parent link="base_link" />
        <child link="nav_link" />
        <axis xyz="0 0 0" />
    </joint>
    <gazebo reference="nav_link">
        <material>Gazebo/Yellow</material>
    </gazebo>
    <link name="arm_L_attach_link">
        <inertial>
            <origin rpy="0 0 0" xyz="0 -8.6877E-18 -0.0040196" />
            <mass value="0.76011" />
            <inertia ixx="0.0053821" ixy="2.3674E-19" ixz="4.3463E-21" iyy="0.0013144" iyz="1.4017E-19" izz="0.0066884" />
        </inertial>
        <visual>
            <origin rpy="0 0 0" xyz="0 0 0" />
            <geometry>
                <mesh filename="package://mmx5_description/meshes/navigation_kit/arm_link.STL" />
            </geometry>
            <material name="">
                <color rgba="0.79216 0.81961 0.93333 1" />
            </material>
        </visual>
        <collision>
            <origin rpy="0 0 0" xyz="0 0 0" />
            <geometry>
                <mesh filename="package://mmx5_description/meshes/navigation_kit/arm_link.STL" />
            </geometry>
        </collision>
    </link>
    <joint name="arm_L_attach_joint" type="fixed">
        <origin rpy="-1.57 0.610865238198017 0" xyz="0.153 0.170000000000003 0.968500000000001" />
        <parent link="base_link" />
        <child link="arm_L_attach_link" />
        <axis xyz="0 0 0" />
    </joint>
    <gazebo reference="arm_L_attach_link">
        <material>Gazebo/Yellow</material>
    </gazebo>
    <link name="arm_R_attach_link">
        <inertial>
            <origin rpy="0 0 0" xyz="0 -8.6877E-18 -0.0040196" />
            <mass value="0.76011" />
            <inertia ixx="0.0053821" ixy="2.3674E-19" ixz="4.3463E-21" iyy="0.0013144" iyz="1.4017E-19" izz="0.0066884" />
        </inertial>
        <visual>
            <origin rpy="0 0 0" xyz="0 0 0" />
            <geometry>
                <mesh filename="package://mmx5_description/meshes/navigation_kit/arm_link.STL" />
            </geometry>
            <material name="">
                <color rgba="0.79216 0.81961 0.93333 1" />
            </material>
        </visual>
        <collision>
            <origin rpy="0 0 0" xyz="0 0 0" />
            <geometry>
                <mesh filename="package://mmx5_description/meshes/navigation_kit/arm_link.STL" />
            </geometry>
        </collision>
    </link>
    <joint name="arm_R_attach_joint" type="fixed">
        <origin rpy="1.57 0.610865238198017 0" xyz="0.153000000000001 -0.1699999999999994 0.968500000000001" />
        <parent link="base_link" />
        <child link="arm_R_attach_link" />
        <axis xyz="0 0 0" />
    </joint>
    <gazebo reference="arm_R_attach_link">
        <material>Gazebo/Yellow</material>
    </gazebo>
    <link name="laser_F_link">
        <inertial>
            <origin rpy="0 0 0" xyz="-0.00392412929938074 0.0152636358577628 -0.0174579858808611" />
            <mass value="0.056359366667149" />
            <inertia ixx="2.55604873034863E-05" ixy="-9.29963736591822E-08" ixz="1.24090858298927E-07" iyy="2.41288595750148E-05" iyz="4.70139180502742E-08" izz="3.58756235470363E-05" />
        </inertial>
        <visual>
            <origin rpy="0 0 0" xyz="0 0 0" />
            <geometry>
                <mesh filename="package://mmx5_description/meshes/sensor/laser_F_link.STL" />
            </geometry>
            <material name="">
                <color rgba="0.941176470588235 0.674509803921569 0.117647058823529 1" />
            </material>
        </visual>
        <collision>
            <origin rpy="0 0 0" xyz="0 0 0" />
            <geometry>
                <mesh filename="package://mmx5_description/meshes/sensor/laser_F_link.STL" />
            </geometry>
        </collision>
    </link>
    <joint name="laser_F_joint" type="fixed">
        <origin rpy="0 0 0" xyz="0.3197 0 0.246819999999998" />
        <parent link="base_link" />
        <child link="laser_F_link" />
        <axis xyz="0 0 0" />
    </joint>
    <gazebo reference="laser_F_link">
        <material>Gazebo/Black</material>
        <sensor name="head_hokuyo_sensor" type="ray">
            <pose>0 0 0 0 0 0</pose>
            <visualize>False</visualize>
            <update_rate>15</update_rate>
            <ray>
                <scan>
                    <horizontal>
                        <samples>180</samples>
                        <resolution>1</resolution>
                        <min_angle>-0.785398</min_angle>
                        <max_angle>0.785398</max_angle>
                    </horizontal>
                </scan>
                <range>
                    <min>0.1</min>
                    <max>30.0</max>
                    <resolution>0.01</resolution>
                </range>
                <noise>
                    <type>gaussian</type>
                    <mean>0.0</mean>
                    <stddev>0.01</stddev>
                </noise>
            </ray>
            <plugin filename="libgazebo_ros_laser.so" name="laser_controller">
                <robotNamespace />
                <frameName>laser_F_link</frameName>
                <topicName>front_scan</topicName>
            </plugin>
        </sensor>
    </gazebo>
    <link name="lidar_link">
        <inertial>
            <origin rpy="0 0 0" xyz="-0.00130047182065299 -8.71661417448629E-05 -0.0237893526295022" />
            <mass value="0.101936733121447" />
            <inertia ixx="0.000117105373757812" ixy="1.11586534809135E-07" ixz="3.34607879442284E-07" iyy="0.000115891247109116" iyz="-2.66539593461626E-08" izz="0.000195379409525254" />
        </inertial>
        <visual>
            <origin rpy="0 0 0" xyz="0 0 0" />
            <geometry>
                <mesh filename="package://mmx5_description/meshes/sensor/lidar_Link.STL" />
            </geometry>
            <material name="">
                <color rgba="0.792156862745098 0.819607843137255 0.933333333333333 1" />
            </material>
        </visual>
        <collision>
            <origin rpy="0 0 0" xyz="0 0 0.0825" />
            <geometry>
                <cylinder length="0.17" radius="0.08449999999999999" />
            </geometry>
        </collision>
    </link>
    <joint name="lidar_joint" type="fixed">
        <origin rpy="0 0 0" xyz="-0.217650773606743 0 0.863000000000001" />
        <parent link="base_link" />
        <child link="lidar_link" />
        <axis xyz="0 0 0" />
    </joint>
    <gazebo reference="lidar_link">
        <!-- GPU Lidar sensor -->
        <sensor name="lidar_link-RS16" type="gpu_ray">
            <!-- The location and direction of the sensor -->
            <pose>0 0 0 0 0 0</pose>
            <!-- Irreversible sensor -->
            <visualize>False</visualize>
            <!-- Update frequency -->
            <update_rate>10</update_rate>
            <ray>
                <!-- Laser scanning attribute -->
                <scan>
                    <!-- Horizontal scanning parameters -->
                    <horizontal>
                        <!-- Number of samples for each scanning -->
                        <samples>1200</samples>
                        <!-- Resolution -->
                        <resolution>1</resolution>
                        <!-- Minimum scanning angle -->
                        <min_angle>-3.141592653589793</min_angle>
                        <!-- Maximum scanning angle -->
                        <max_angle>3.141592653589793</max_angle>
                    </horizontal>
                    <!-- Vertical scanning parameters -->
                    <vertical>
                        <!-- Number of samples for each scanning -->
                        <samples>16</samples>
                        <!-- Resolution -->
                        <resolution>1</resolution>
                        <!-- Minimum scanning angle -->
                        <min_angle>-0.2617993877991494</min_angle>
                        <!-- Maximum scanning angle -->
                        <max_angle>0.2617993877991494</max_angle>
                    </vertical>
                </scan>
                <!-- Ranging range attribute -->
                <range>
                    <!-- Minimum ranging range -->
                    <min>0.4</min>
                    <!-- Maximum ranging range -->
                    <max>150.0</max>
                    <!-- Ranging resolution -->
                    <resolution>0.001</resolution>
                </range>
                <!-- Noise attribute -->
                <noise>
                    <!-- Noise Type: Gaos Noise -->
                    <type>gaussian</type>
                    <!-- Noise average -->
                    <mean>0.0</mean>
                    <!-- Noise difference -->
                    <stddev>0.0</stddev>
                </noise>
            </ray>
            <plugin filename="libgazebo_ros_robosense_gpu_laser.so" name="gazebo_ros_laser_controller">
                <topicName>rslidar_points</topicName>
                <frameName>lidar_link</frameName>
                <min_range>0.4</min_range>
                <max_range>150.0</max_range>
                <gaussianNoise>0.008</gaussianNoise>
            </plugin>
        </sensor>
    </gazebo>
    <gazebo reference="lidar_link">
        <material>Gazebo/Black</material>
    </gazebo>
    <link name="imu_link">
        <inertial>
            <origin rpy="0 0 0" xyz="0.00121234966136663 0.000180494940162676 0.0118745134365582" />
            <mass value="0.0535116339200075" />
            <inertia ixx="1.26988062647507E-05" ixy="-2.97639397412748E-07" ixz="5.67467567831883E-08" iyy="1.23266099221182E-05" iyz="8.44297636640416E-09" izz="2.0045369445872E-05" />
        </inertial>
        <visual>
            <origin rpy="0 0 0" xyz="0 0 0" />
            <geometry>
                <mesh filename="package://mmx5_description/meshes/sensor/imu_Link.STL" />
            </geometry>
            <material name="">
                <color rgba="0.298039215686275 0.298039215686275 0.298039215686275 1" />
            </material>
        </visual>
        <collision>
            <origin rpy="0 0 0" xyz="0 0 0" />
            <geometry>
                <mesh filename="package://mmx5_description/meshes/sensor/imu_Link.STL" />
            </geometry>
        </collision>
    </link>
    <joint name="imu_link_joint" type="fixed">
        <origin rpy="0 0 0" xyz="-0.232650773606743 0 0.703500000000001" />
        <parent link="base_link" />
        <child link="imu_link" />
        <axis xyz="0 0 0" />
    </joint>
    <gazebo reference="imu_link_joint">
        <preserveFixedJoint>true</preserveFixedJoint>
        <!-- <preserveFixedJoint>true</preserveFixedJoint> -->
    </gazebo>
    <gazebo reference="imu_link" />
    <gazebo reference="imu_link">
        <gravity>False</gravity>
        <sensor name="imu_sensor" type="imu">
            <always_on>True</always_on>
            <update_rate>10</update_rate>
            <visualize>True</visualize>
            <topic>imu_link</topic>
            <plugin filename="libgazebo_ros_imu_sensor.so" name="imu_plugin">
                <topicName>imu/data</topicName>
                <bodyName>imu_link</bodyName>
                <updateRateHZ>10.0</updateRateHZ>
                <gaussianNoise>0.0</gaussianNoise>
                <xyzOffset>0 0 0</xyzOffset>
                <rpyOffset>0 0 0</rpyOffset>
                <frameName>imu_link</frameName>
                <initialOrientationAsReference>True</initialOrientationAsReference>
            </plugin>
            <pose>0 0 0 0 0 0</pose>
        </sensor>
    </gazebo>
    <link name="rtk_ant_M_link">
        <inertial>
            <origin rpy="0 0 0" xyz="5.55111512312578E-17 -1.33226762955019E-15 0.119247028988802" />
            <mass value="0.435239721235919" />
            <inertia ixx="0.000665972237511948" ixy="1.54074395550979E-33" ixz="-1.02758469017719E-20" iyy="0.000665972237511948" iyz="-2.17195909848501E-18" izz="0.000853452872320831" />
        </inertial>
        <visual>
            <origin rpy="0 0 0" xyz="0 0 0" />
            <geometry>
                <mesh filename="package://mmx5_description/meshes/sensor/rtk.STL" />
            </geometry>
            <material name="">
                <color rgba="0.941176470588235 0.674509803921569 0.117647058823529 1" />
            </material>
        </visual>
        <collision>
            <origin rpy="0 0 0" xyz="0 0 0" />
            <geometry>
                <mesh filename="package://mmx5_description/meshes/sensor/rtk.STL" />
            </geometry>
        </collision>
    </link>
    <joint name="rtk_ant_M_joint" type="fixed">
        <origin rpy="0 0 0" xyz="-0.229592523325443 0.296267949192464 0.622423048454134" />
        <parent link="base_link" />
        <child link="rtk_ant_M_link" />
        <axis xyz="0 0 0" />
    </joint>
    <link name="rtk_ant_S_link">
        <inertial>
            <origin rpy="0 0 0" xyz="5.55111512312578E-17 -1.33226762955019E-15 0.119247028988802" />
            <mass value="0.435239721235919" />
            <inertia ixx="0.000665972237511948" ixy="1.54074395550979E-33" ixz="-1.02758469017719E-20" iyy="0.000665972237511948" iyz="-2.17195909848501E-18" izz="0.000853452872320831" />
        </inertial>
        <visual>
            <origin rpy="0 0 0" xyz="0 0 0" />
            <geometry>
                <mesh filename="package://mmx5_description/meshes/sensor/rtk.STL" />
            </geometry>
            <material name="">
                <color rgba="0.941176470588235 0.674509803921569 0.117647058823529 1" />
            </material>
        </visual>
        <collision>
            <origin rpy="0 0 0" xyz="0 0 0" />
            <geometry>
                <mesh filename="package://mmx5_description/meshes/sensor/rtk.STL" />
            </geometry>
        </collision>
    </link>
    <joint name="rtk_ant_S_joint" type="fixed">
        <origin rpy="0 0 0" xyz="-0.229592523325462 -0.296267949192412 0.622423048454133" />
        <parent link="base_link" />
        <child link="rtk_ant_S_link" />
        <axis xyz="0 0 0" />
    </joint>
    <joint name="left_fr3_joint_arm_L_attach_link" type="fixed">
        <parent link="arm_L_attach_link" />
        <child link="left_fr3_link0" />
        <origin rpy="0 0 0" xyz="0 0 0" />
    </joint>
    <!-- sub-link defining detailed meshes for collision with environment -->
    <link name="left_fr3_link0">
        <visual>
            <geometry>
                <mesh filename="package://franka_description/meshes/visual/link0.dae" />
            </geometry>
        </visual>
        <collision>
            <geometry>
                <mesh filename="package://franka_description/meshes/collision/link0.stl" />
            </geometry>
        </collision>
        <inertial>
            <mass value="0.1" />
            <origin xyz="0 0 0" rpy="0 0 0" />
            <inertia ixx="0.03" iyy="0.03" izz="0.03" ixy="0.0" ixz="0.0" iyz="0.0" />
        </inertial>
    </link>
    <!-- sub-link defining coarse geometries of real robot's internal self-collision -->
    <link name="left_fr3_link0_sc">
        <collision>
            <origin rpy="0 1.5707963267948966 0" xyz="-0.075 0 0.06" />
            <geometry>
                <cylinder length="0.03" radius="0.09" />
            </geometry>
        </collision>
        <collision>
            <origin xyz="-0.06 0 0.06" />
            <geometry>
                <sphere radius="0.09" />
            </geometry>
        </collision>
        <collision>
            <origin xyz="-0.09 0 0.06" />
            <geometry>
                <sphere radius="0.09" />
            </geometry>
        </collision>
        <inertial>
            <mass value="0.1" />
            <origin xyz="0 0 0" rpy="0 0 0" />
            <inertia ixx="0.03" iyy="0.03" izz="0.03" ixy="0.0" ixz="0.0" iyz="0.0" />
        </inertial>
    </link>
    <!-- fixed joint between both sub-links -->
    <joint name="left_fr3_link0_sc_joint" type="fixed">
        <origin rpy="0 0 0" />
        <parent link="left_fr3_link0" />
        <child link="left_fr3_link0_sc" />
    </joint>
    <!-- sub-link defining detailed meshes for collision with environment -->
    <link name="left_fr3_link1">
        <visual>
            <geometry>
                <mesh filename="package://franka_description/meshes/visual/link1.dae" />
            </geometry>
        </visual>
        <collision>
            <geometry>
                <mesh filename="package://franka_description/meshes/collision/link1.stl" />
            </geometry>
        </collision>
        <inertial>
            <mass value="0.1" />
            <origin xyz="0 0 0" rpy="0 0 0" />
            <inertia ixx="0.03" iyy="0.03" izz="0.03" ixy="0.0" ixz="0.0" iyz="0.0" />
        </inertial>
    </link>
    <!-- sub-link defining coarse geometries of real robot's internal self-collision -->
    <link name="left_fr3_link1_sc">
        <collision>
            <origin rpy="0 0 0" xyz="0 0 -0.1915" />
            <geometry>
                <cylinder length="0.283" radius="0.09" />
            </geometry>
        </collision>
        <collision>
            <origin xyz="0 0 -0.05000000000000002" />
            <geometry>
                <sphere radius="0.09" />
            </geometry>
        </collision>
        <collision>
            <origin xyz="0 0 -0.33299999999999996" />
            <geometry>
                <sphere radius="0.09" />
            </geometry>
        </collision>
        <inertial>
            <mass value="0.1" />
            <origin xyz="0 0 0" rpy="0 0 0" />
            <inertia ixx="0.03" iyy="0.03" izz="0.03" ixy="0.0" ixz="0.0" iyz="0.0" />
        </inertial>
    </link>
    <!-- fixed joint between both sub-links -->
    <joint name="left_fr3_link1_sc_joint" type="fixed">
        <origin rpy="0 0 0" />
        <parent link="left_fr3_link1" />
        <child link="left_fr3_link1_sc" />
    </joint>
    <joint name="left_fr3_joint1" type="revolute">
        <origin rpy="0 0 0" xyz="0 0 0.333" />
        <parent link="left_fr3_link0" />
        <child link="left_fr3_link1" />
        <axis xyz="0 0 1" />
        <limit effort="87.0" lower="-2.8973" upper="2.8973" velocity="2.175" />
        <safety_controller k_position="100.0" k_velocity="40.0" soft_lower_limit="-2.8973" soft_upper_limit="2.8973" />
        <dynamics D="1" K="7000" damping="0.003" friction="0.0" mu_coulomb="0" mu_viscous="16" />
    </joint>
    <!-- sub-link defining detailed meshes for collision with environment -->
    <link name="left_fr3_link2">
        <visual>
            <geometry>
                <mesh filename="package://franka_description/meshes/visual/link2.dae" />
            </geometry>
        </visual>
        <collision>
            <geometry>
                <mesh filename="package://franka_description/meshes/collision/link2.stl" />
            </geometry>
        </collision>
        <inertial>
            <mass value="0.1" />
            <origin xyz="0 0 0" rpy="0 0 0" />
            <inertia ixx="0.03" iyy="0.03" izz="0.03" ixy="0.0" ixz="0.0" iyz="0.0" />
        </inertial>
    </link>
    <!-- sub-link defining coarse geometries of real robot's internal self-collision -->
    <link name="left_fr3_link2_sc">
        <collision>
            <origin rpy="0 0 0" xyz="0 0 0" />
            <geometry>
                <cylinder length="0.12" radius="0.09" />
            </geometry>
        </collision>
        <collision>
            <origin xyz="0 0 0.06" />
            <geometry>
                <sphere radius="0.09" />
            </geometry>
        </collision>
        <collision>
            <origin xyz="0 0 -0.06" />
            <geometry>
                <sphere radius="0.09" />
            </geometry>
        </collision>
        <inertial>
            <mass value="0.1" />
            <origin xyz="0 0 0" rpy="0 0 0" />
            <inertia ixx="0.03" iyy="0.03" izz="0.03" ixy="0.0" ixz="0.0" iyz="0.0" />
        </inertial>
    </link>
    <!-- fixed joint between both sub-links -->
    <joint name="left_fr3_link2_sc_joint" type="fixed">
        <origin rpy="0 0 0" />
        <parent link="left_fr3_link2" />
        <child link="left_fr3_link2_sc" />
    </joint>
    <joint name="left_fr3_joint2" type="revolute">
        <origin rpy="-1.5707963267948966 0 0" xyz="0 0 0" />
        <parent link="left_fr3_link1" />
        <child link="left_fr3_link2" />
        <axis xyz="0 0 1" />
        <limit effort="87.0" lower="-1.7628" upper="1.7628" velocity="2.175" />
        <safety_controller k_position="100.0" k_velocity="40.0" soft_lower_limit="-1.7628" soft_upper_limit="1.7628" />
        <dynamics D="1" K="7000" damping="0.003" friction="0.0" mu_coulomb="0" mu_viscous="16" />
    </joint>
    <!-- sub-link defining detailed meshes for collision with environment -->
    <link name="left_fr3_link3">
        <visual>
            <geometry>
                <mesh filename="package://franka_description/meshes/visual/link3.dae" />
            </geometry>
        </visual>
        <collision>
            <geometry>
                <mesh filename="package://franka_description/meshes/collision/link3.stl" />
            </geometry>
        </collision>
        <inertial>
            <mass value="0.1" />
            <origin xyz="0 0 0" rpy="0 0 0" />
            <inertia ixx="0.03" iyy="0.03" izz="0.03" ixy="0.0" ixz="0.0" iyz="0.0" />
        </inertial>
    </link>
    <!-- sub-link defining coarse geometries of real robot's internal self-collision -->
    <link name="left_fr3_link3_sc">
        <collision>
            <origin rpy="0 0 0" xyz="0 0 -0.145" />
            <geometry>
                <cylinder length="0.15" radius="0.09" />
            </geometry>
        </collision>
        <collision>
            <origin xyz="0 0 -0.06999999999999999" />
            <geometry>
                <sphere radius="0.09" />
            </geometry>
        </collision>
        <collision>
            <origin xyz="0 0 -0.21999999999999997" />
            <geometry>
                <sphere radius="0.09" />
            </geometry>
        </collision>
        <inertial>
            <mass value="0.1" />
            <origin xyz="0 0 0" rpy="0 0 0" />
            <inertia ixx="0.03" iyy="0.03" izz="0.03" ixy="0.0" ixz="0.0" iyz="0.0" />
        </inertial>
    </link>
    <!-- fixed joint between both sub-links -->
    <joint name="left_fr3_link3_sc_joint" type="fixed">
        <origin rpy="0 0 0" />
        <parent link="left_fr3_link3" />
        <child link="left_fr3_link3_sc" />
    </joint>
    <joint name="left_fr3_joint3" type="revolute">
        <origin rpy="1.5707963267948966 0 0" xyz="0 -0.316 0" />
        <parent link="left_fr3_link2" />
        <child link="left_fr3_link3" />
        <axis xyz="0 0 1" />
        <limit effort="87.0" lower="-2.8973" upper="2.8973" velocity="2.175" />
        <safety_controller k_position="100.0" k_velocity="40.0" soft_lower_limit="-2.8973" soft_upper_limit="2.8973" />
        <dynamics D="1" K="7000" damping="0.003" friction="0.0" mu_coulomb="0" mu_viscous="16" />
    </joint>
    <!-- sub-link defining detailed meshes for collision with environment -->
    <link name="left_fr3_link4">
        <visual>
            <geometry>
                <mesh filename="package://franka_description/meshes/visual/link4.dae" />
            </geometry>
        </visual>
        <collision>
            <geometry>
                <mesh filename="package://franka_description/meshes/collision/link4.stl" />
            </geometry>
        </collision>
        <inertial>
            <mass value="0.1" />
            <origin xyz="0 0 0" rpy="0 0 0" />
            <inertia ixx="0.03" iyy="0.03" izz="0.03" ixy="0.0" ixz="0.0" iyz="0.0" />
        </inertial>
    </link>
    <!-- sub-link defining coarse geometries of real robot's internal self-collision -->
    <link name="left_fr3_link4_sc">
        <collision>
            <origin rpy="0 0 0" xyz="0 0 0" />
            <geometry>
                <cylinder length="0.12" radius="0.09" />
            </geometry>
        </collision>
        <collision>
            <origin xyz="0 0 0.06" />
            <geometry>
                <sphere radius="0.09" />
            </geometry>
        </collision>
        <collision>
            <origin xyz="0 0 -0.06" />
            <geometry>
                <sphere radius="0.09" />
            </geometry>
        </collision>
        <inertial>
            <mass value="0.1" />
            <origin xyz="0 0 0" rpy="0 0 0" />
            <inertia ixx="0.03" iyy="0.03" izz="0.03" ixy="0.0" ixz="0.0" iyz="0.0" />
        </inertial>
    </link>
    <!-- fixed joint between both sub-links -->
    <joint name="left_fr3_link4_sc_joint" type="fixed">
        <origin rpy="0 0 0" />
        <parent link="left_fr3_link4" />
        <child link="left_fr3_link4_sc" />
    </joint>
    <joint name="left_fr3_joint4" type="revolute">
        <origin rpy="1.5707963267948966 0 0" xyz="0.0825 0 0" />
        <parent link="left_fr3_link3" />
        <child link="left_fr3_link4" />
        <axis xyz="0 0 1" />
        <limit effort="87.0" lower="-3.0718" upper="-0.0698" velocity="2.175" />
        <safety_controller k_position="100.0" k_velocity="40.0" soft_lower_limit="-3.0718" soft_upper_limit="-0.0698" />
        <dynamics D="1" K="7000" damping="0.003" friction="0.0" mu_coulomb="0" mu_viscous="16" />
    </joint>
    <!-- sub-link defining detailed meshes for collision with environment -->
    <link name="left_fr3_link5">
        <visual>
            <geometry>
                <mesh filename="package://franka_description/meshes/visual/link5.dae" />
            </geometry>
        </visual>
        <collision>
            <geometry>
                <mesh filename="package://franka_description/meshes/collision/link5.stl" />
            </geometry>
        </collision>
        <inertial>
            <mass value="0.1" />
            <origin xyz="0 0 0" rpy="0 0 0" />
            <inertia ixx="0.03" iyy="0.03" izz="0.03" ixy="0.0" ixz="0.0" iyz="0.0" />
        </inertial>
    </link>
    <!-- sub-link defining coarse geometries of real robot's internal self-collision -->
    <link name="left_fr3_link5_sc">
        <collision>
            <origin rpy="0 0 0" xyz="0 0 -0.26" />
            <geometry>
                <cylinder length="0.1" radius="0.09" />
            </geometry>
        </collision>
        <collision>
            <origin xyz="0 0 -0.21000000000000002" />
            <geometry>
                <sphere radius="0.09" />
            </geometry>
        </collision>
        <collision>
            <origin xyz="0 0 -0.31" />
            <geometry>
                <sphere radius="0.09" />
            </geometry>
        </collision>
        <collision>
            <origin rpy="0 0 0.08" xyz="0 0.08 -0.13" />
            <geometry>
                <cylinder length="0.14" radius="0.055" />
            </geometry>
        </collision>
        <collision>
            <origin xyz="0 0.08 -0.06" />
            <geometry>
                <sphere radius="0.055" />
            </geometry>
        </collision>
        <collision>
            <origin xyz="0 0.08 -0.2" />
            <geometry>
                <sphere radius="0.055" />
            </geometry>
        </collision>
        <inertial>
            <mass value="0.1" />
            <origin xyz="0 0 0" rpy="0 0 0" />
            <inertia ixx="0.03" iyy="0.03" izz="0.03" ixy="0.0" ixz="0.0" iyz="0.0" />
        </inertial>
    </link>
    <!-- fixed joint between both sub-links -->
    <joint name="left_fr3_link5_sc_joint" type="fixed">
        <origin rpy="0 0 0" />
        <parent link="left_fr3_link5" />
        <child link="left_fr3_link5_sc" />
    </joint>
    <joint name="left_fr3_joint5" type="revolute">
        <origin rpy="-1.5707963267948966 0 0" xyz="-0.0825 0.384 0" />
        <parent link="left_fr3_link4" />
        <child link="left_fr3_link5" />
        <axis xyz="0 0 1" />
        <limit effort="12.0" lower="-2.8973" upper="2.8973" velocity="2.61" />
        <safety_controller k_position="100.0" k_velocity="40.0" soft_lower_limit="-2.8973" soft_upper_limit="2.8973" />
        <dynamics D="1" K="7000" damping="0.003" friction="0.0" mu_coulomb="0" mu_viscous="16" />
    </joint>
    <!-- sub-link defining detailed meshes for collision with environment -->
    <link name="left_fr3_link6">
        <visual>
            <geometry>
                <mesh filename="package://franka_description/meshes/visual/link6.dae" />
            </geometry>
        </visual>
        <collision>
            <geometry>
                <mesh filename="package://franka_description/meshes/collision/link6.stl" />
            </geometry>
        </collision>
        <inertial>
            <mass value="0.1" />
            <origin xyz="0 0 0" rpy="0 0 0" />
            <inertia ixx="0.03" iyy="0.03" izz="0.03" ixy="0.0" ixz="0.0" iyz="0.0" />
        </inertial>
    </link>
    <!-- sub-link defining coarse geometries of real robot's internal self-collision -->
    <link name="left_fr3_link6_sc">
        <collision>
            <origin rpy="0 0 0" xyz="0 0 -0.03" />
            <geometry>
                <cylinder length="0.08" radius="0.08" />
            </geometry>
        </collision>
        <collision>
            <origin xyz="0 0 0.010000000000000002" />
            <geometry>
                <sphere radius="0.08" />
            </geometry>
        </collision>
        <collision>
            <origin xyz="0 0 -0.07" />
            <geometry>
                <sphere radius="0.08" />
            </geometry>
        </collision>
        <inertial>
            <mass value="0.1" />
            <origin xyz="0 0 0" rpy="0 0 0" />
            <inertia ixx="0.03" iyy="0.03" izz="0.03" ixy="0.0" ixz="0.0" iyz="0.0" />
        </inertial>
    </link>
    <!-- fixed joint between both sub-links -->
    <joint name="left_fr3_link6_sc_joint" type="fixed">
        <origin rpy="0 0 0" />
        <parent link="left_fr3_link6" />
        <child link="left_fr3_link6_sc" />
    </joint>
    <joint name="left_fr3_joint6" type="revolute">
        <origin rpy="1.5707963267948966 0 0" xyz="0 0 0" />
        <parent link="left_fr3_link5" />
        <child link="left_fr3_link6" />
        <axis xyz="0 0 1" />
        <limit effort="12.0" lower="-0.0175" upper="3.7525" velocity="2.61" />
        <safety_controller k_position="100.0" k_velocity="40.0" soft_lower_limit="-0.0175" soft_upper_limit="3.7525" />
        <dynamics D="1" K="7000" damping="0.003" friction="0.0" mu_coulomb="0" mu_viscous="16" />
    </joint>
    <!-- sub-link defining detailed meshes for collision with environment -->
    <link name="left_fr3_link7">
        <visual>
            <geometry>
                <mesh filename="package://franka_description/meshes/visual/link7.dae" />
            </geometry>
        </visual>
        <collision>
            <geometry>
                <mesh filename="package://franka_description/meshes/collision/link7.stl" />
            </geometry>
        </collision>
        <inertial>
            <mass value="0.1" />
            <origin xyz="0 0 0" rpy="0 0 0" />
            <inertia ixx="0.03" iyy="0.03" izz="0.03" ixy="0.0" ixz="0.0" iyz="0.0" />
        </inertial>
    </link>
    <!-- sub-link defining coarse geometries of real robot's internal self-collision -->
    <link name="left_fr3_link7_sc">
        <collision>
            <origin rpy="0 0 0" xyz="0 0 0.01" />
            <geometry>
                <cylinder length="0.14" radius="0.07" />
            </geometry>
        </collision>
        <collision>
            <origin xyz="0 0 0.08" />
            <geometry>
                <sphere radius="0.07" />
            </geometry>
        </collision>
        <collision>
            <origin xyz="0 0 -0.060000000000000005" />
            <geometry>
                <sphere radius="0.07" />
            </geometry>
        </collision>
        <collision>
            <origin rpy="0 1.5707963267948966 0" xyz="0.06 0 0.082" />
            <geometry>
                <cylinder length="0.01" radius="0.06" />
            </geometry>
        </collision>
        <collision>
            <origin xyz="0.065 0 0.082" />
            <geometry>
                <sphere radius="0.06" />
            </geometry>
        </collision>
        <collision>
            <origin xyz="0.055 0 0.082" />
            <geometry>
                <sphere radius="0.06" />
            </geometry>
        </collision>
        <inertial>
            <mass value="0.1" />
            <origin xyz="0 0 0" rpy="0 0 0" />
            <inertia ixx="0.03" iyy="0.03" izz="0.03" ixy="0.0" ixz="0.0" iyz="0.0" />
        </inertial>
    </link>
    <!-- fixed joint between both sub-links -->
    <joint name="left_fr3_link7_sc_joint" type="fixed">
        <origin rpy="0 0 0.7853981633974483" />
        <parent link="left_fr3_link7" />
        <child link="left_fr3_link7_sc" />
    </joint>
    <joint name="left_fr3_joint7" type="revolute">
        <origin rpy="1.5707963267948966 0 0" xyz="0.088 0 0" />
        <parent link="left_fr3_link6" />
        <child link="left_fr3_link7" />
        <axis xyz="0 0 1" />
        <limit effort="12.0" lower="-2.8973" upper="2.8973" velocity="2.61" />
        <safety_controller k_position="100.0" k_velocity="40.0" soft_lower_limit="-2.8973" soft_upper_limit="2.8973" />
        <dynamics D="1" K="7000" damping="0.003" friction="0.0" mu_coulomb="0" mu_viscous="16" />
    </joint>
    <link name="left_fr3_link8" />
    <joint name="left_fr3_joint8" type="fixed">
        <origin rpy="0 0 0" xyz="0 0 0.107" />
        <parent link="left_fr3_link7" />
        <child link="left_fr3_link8" />
    </joint>
    <joint name="left_fr3_hand_joint" type="fixed">
        <parent link="left_fr3_link8" />
        <child link="left_fr3_hand" />
        <origin rpy="0 0 -0.7853981633974483" xyz="0 0 0" />
    </joint>
    <!-- sub-link defining detailed meshes for collision with environment -->
    <link name="left_fr3_hand">
        <visual>
            <geometry>
                <mesh filename="package://franka_description/meshes/visual/hand.dae" />
            </geometry>
        </visual>
        <collision>
            <geometry>
                <mesh filename="package://franka_description/meshes/collision/hand.stl" />
            </geometry>
        </collision>
        <inertial>
            <mass value="0.1" />
            <origin xyz="0 0 0" rpy="0 0 0" />
            <inertia ixx="0.03" iyy="0.03" izz="0.03" ixy="0.0" ixz="0.0" iyz="0.0" />
        </inertial>
    </link>
    <!-- sub-link defining coarse geometries of real robot's internal self-collision -->
    <link name="left_fr3_hand_sc">
        <collision>
            <origin rpy="1.5707963267948966 0 0" xyz="0 0 0.04" />
            <geometry>
                <cylinder length="0.1" radius="0.07" />
            </geometry>
        </collision>
        <collision>
            <origin xyz="0 0.05 0.04" />
            <geometry>
                <sphere radius="0.07" />
            </geometry>
        </collision>
        <collision>
            <origin xyz="0 -0.05 0.04" />
            <geometry>
                <sphere radius="0.07" />
            </geometry>
        </collision>
        <collision>
            <origin rpy="1.5707963267948966 0 0" xyz="0 0 0.1" />
            <geometry>
                <cylinder length="0.1" radius="0.05" />
            </geometry>
        </collision>
        <collision>
            <origin xyz="0 0.05 0.1" />
            <geometry>
                <sphere radius="0.05" />
            </geometry>
        </collision>
        <collision>
            <origin xyz="0 -0.05 0.1" />
            <geometry>
                <sphere radius="0.05" />
            </geometry>
        </collision>
        <inertial>
            <mass value="0.1" />
            <origin xyz="0 0 0" rpy="0 0 0" />
            <inertia ixx="0.03" iyy="0.03" izz="0.03" ixy="0.0" ixz="0.0" iyz="0.0" />
        </inertial>
    </link>
    <!-- fixed joint between both sub-links -->
    <joint name="left_fr3_hand_sc_joint" type="fixed">
        <origin rpy="0 0 0" />
        <parent link="left_fr3_hand" />
        <child link="left_fr3_hand_sc" />
    </joint>
    <!-- Define the hand_tcp frame -->
    <link name="left_fr3_hand_tcp" />
    <joint name="left_fr3_hand_tcp_joint" type="fixed">
        <origin rpy="0 0 0" xyz="0 0 0.1034" />
        <parent link="left_fr3_hand" />
        <child link="left_fr3_hand_tcp" />
    </joint>
    <link name="left_fr3_leftfinger">
        <visual>
            <geometry>
                <mesh filename="package://franka_description/meshes/visual/finger.dae" />
            </geometry>
        </visual>
        <!-- screw mount -->
        <collision>
            <origin rpy="0 0 0" xyz="0 18.5e-3 11e-3" />
            <geometry>
                <box size="22e-3 15e-3 20e-3" />
            </geometry>
        </collision>
        <!-- cartriage sledge -->
        <collision>
            <origin rpy="0 0 0" xyz="0 6.8e-3 2.2e-3" />
            <geometry>
                <box size="22e-3 8.8e-3 3.8e-3" />
            </geometry>
        </collision>
        <!-- diagonal finger -->
        <collision>
            <origin rpy="0.5235987755982988 0 0" xyz="0 15.9e-3 28.35e-3" />
            <geometry>
                <box size="17.5e-3 7e-3 23.5e-3" />
            </geometry>
        </collision>
        <!-- rubber tip with which to grasp -->
        <collision>
            <origin rpy="0 0 0" xyz="0 7.58e-3 45.25e-3" />
            <geometry>
                <box size="17.5e-3 15.2e-3 18.5e-3" />
            </geometry>
        </collision>
        <inertial>
            <mass value="0.1" />
            <origin xyz="0 0 0" rpy="0 0 0" />
            <inertia ixx="0.03" iyy="0.03" izz="0.03" ixy="0.0" ixz="0.0" iyz="0.0" />
        </inertial>
    </link>
    <link name="left_fr3_rightfinger">
        <visual>
            <origin rpy="0 0 3.141592653589793" xyz="0 0 0" />
            <geometry>
                <mesh filename="package://franka_description/meshes/visual/finger.dae" />
            </geometry>
        </visual>
        <!-- screw mount -->
        <collision>
            <origin rpy="0 0 0" xyz="0 -18.5e-3 11e-3" />
            <geometry>
                <box size="22e-3 15e-3 20e-3" />
            </geometry>
        </collision>
        <!-- cartriage sledge -->
        <collision>
            <origin rpy="0 0 0" xyz="0 -6.8e-3 2.2e-3" />
            <geometry>
                <box size="22e-3 8.8e-3 3.8e-3" />
            </geometry>
        </collision>
        <!-- diagonal finger -->
        <collision>
            <origin rpy="-0.5235987755982988 0 0" xyz="0 -15.9e-3 28.35e-3" />
            <geometry>
                <box size="17.5e-3 7e-3 23.5e-3" />
            </geometry>
        </collision>
        <!-- rubber tip with which to grasp -->
        <collision>
            <origin rpy="0 0 0" xyz="0 -7.58e-3 45.25e-3" />
            <geometry>
                <box size="17.5e-3 15.2e-3 18.5e-3" />
            </geometry>
        </collision>
        <inertial>
            <mass value="0.1" />
            <origin xyz="0 0 0" rpy="0 0 0" />
            <inertia ixx="0.03" iyy="0.03" izz="0.03" ixy="0.0" ixz="0.0" iyz="0.0" />
        </inertial>
    </link>
    <joint name="left_fr3_finger_joint1" type="prismatic">
        <parent link="left_fr3_hand" />
        <child link="left_fr3_leftfinger" />
        <origin rpy="0 0 0" xyz="0 0 0.0584" />
        <axis xyz="0 1 0" />
        <limit effort="100" lower="0.0" upper="0.04" velocity="0.2" />
        <dynamics damping="0.3" />
    </joint>
    <joint name="left_fr3_finger_joint2" type="prismatic">
        <parent link="left_fr3_hand" />
        <child link="left_fr3_rightfinger" />
        <origin rpy="0 0 0" xyz="0 0 0.0584" />
        <axis xyz="0 -1 0" />
        <limit effort="100" lower="0.0" upper="0.04" velocity="0.2" />
        <mimic joint="left_fr3_finger_joint1" />
        <dynamics damping="0.3" />
    </joint>
    <joint name="right_fr3_joint_arm_R_attach_link" type="fixed">
        <parent link="arm_R_attach_link" />
        <child link="right_fr3_link0" />
        <origin rpy="0 0 0" xyz="0 0 0" />
    </joint>
    <!-- sub-link defining detailed meshes for collision with environment -->
    <link name="right_fr3_link0">
        <visual>
            <geometry>
                <mesh filename="package://franka_description/meshes/visual/link0.dae" />
            </geometry>
        </visual>
        <collision>
            <geometry>
                <mesh filename="package://franka_description/meshes/collision/link0.stl" />
            </geometry>
        </collision>
        <inertial>
            <mass value="0.1" />
            <origin xyz="0 0 0" rpy="0 0 0" />
            <inertia ixx="0.03" iyy="0.03" izz="0.03" ixy="0.0" ixz="0.0" iyz="0.0" />
        </inertial>
    </link>
    <!-- sub-link defining coarse geometries of real robot's internal self-collision -->
    <link name="right_fr3_link0_sc">
        <collision>
            <origin rpy="0 1.5707963267948966 0" xyz="-0.075 0 0.06" />
            <geometry>
                <cylinder length="0.03" radius="0.09" />
            </geometry>
        </collision>
        <collision>
            <origin xyz="-0.06 0 0.06" />
            <geometry>
                <sphere radius="0.09" />
            </geometry>
        </collision>
        <collision>
            <origin xyz="-0.09 0 0.06" />
            <geometry>
                <sphere radius="0.09" />
            </geometry>
        </collision>
        <inertial>
            <mass value="0.1" />
            <origin xyz="0 0 0" rpy="0 0 0" />
            <inertia ixx="0.03" iyy="0.03" izz="0.03" ixy="0.0" ixz="0.0" iyz="0.0" />
        </inertial>
    </link>
    <!-- fixed joint between both sub-links -->
    <joint name="right_fr3_link0_sc_joint" type="fixed">
        <origin rpy="0 0 0" />
        <parent link="right_fr3_link0" />
        <child link="right_fr3_link0_sc" />
    </joint>
    <!-- sub-link defining detailed meshes for collision with environment -->
    <link name="right_fr3_link1">
        <visual>
            <geometry>
                <mesh filename="package://franka_description/meshes/visual/link1.dae" />
            </geometry>
        </visual>
        <collision>
            <geometry>
                <mesh filename="package://franka_description/meshes/collision/link1.stl" />
            </geometry>
        </collision>
        <inertial>
            <mass value="0.1" />
            <origin xyz="0 0 0" rpy="0 0 0" />
            <inertia ixx="0.03" iyy="0.03" izz="0.03" ixy="0.0" ixz="0.0" iyz="0.0" />
        </inertial>
    </link>
    <!-- sub-link defining coarse geometries of real robot's internal self-collision -->
    <link name="right_fr3_link1_sc">
        <collision>
            <origin rpy="0 0 0" xyz="0 0 -0.1915" />
            <geometry>
                <cylinder length="0.283" radius="0.09" />
            </geometry>
        </collision>
        <collision>
            <origin xyz="0 0 -0.05000000000000002" />
            <geometry>
                <sphere radius="0.09" />
            </geometry>
        </collision>
        <collision>
            <origin xyz="0 0 -0.33299999999999996" />
            <geometry>
                <sphere radius="0.09" />
            </geometry>
        </collision>
        <inertial>
            <mass value="0.1" />
            <origin xyz="0 0 0" rpy="0 0 0" />
            <inertia ixx="0.03" iyy="0.03" izz="0.03" ixy="0.0" ixz="0.0" iyz="0.0" />
        </inertial>
    </link>
    <!-- fixed joint between both sub-links -->
    <joint name="right_fr3_link1_sc_joint" type="fixed">
        <origin rpy="0 0 0" />
        <parent link="right_fr3_link1" />
        <child link="right_fr3_link1_sc" />
    </joint>
    <joint name="right_fr3_joint1" type="revolute">
        <origin rpy="0 0 0" xyz="0 0 0.333" />
        <parent link="right_fr3_link0" />
        <child link="right_fr3_link1" />
        <axis xyz="0 0 1" />
        <limit effort="87.0" lower="-2.8973" upper="2.8973" velocity="2.175" />
        <safety_controller k_position="100.0" k_velocity="40.0" soft_lower_limit="-2.8973" soft_upper_limit="2.8973" />
        <dynamics D="1" K="7000" damping="0.003" friction="0.0" mu_coulomb="0" mu_viscous="16" />
    </joint>
    <!-- sub-link defining detailed meshes for collision with environment -->
    <link name="right_fr3_link2">
        <visual>
            <geometry>
                <mesh filename="package://franka_description/meshes/visual/link2.dae" />
            </geometry>
        </visual>
        <collision>
            <geometry>
                <mesh filename="package://franka_description/meshes/collision/link2.stl" />
            </geometry>
        </collision>
        <inertial>
            <mass value="0.1" />
            <origin xyz="0 0 0" rpy="0 0 0" />
            <inertia ixx="0.03" iyy="0.03" izz="0.03" ixy="0.0" ixz="0.0" iyz="0.0" />
        </inertial>
    </link>
    <!-- sub-link defining coarse geometries of real robot's internal self-collision -->
    <link name="right_fr3_link2_sc">
        <collision>
            <origin rpy="0 0 0" xyz="0 0 0" />
            <geometry>
                <cylinder length="0.12" radius="0.09" />
            </geometry>
        </collision>
        <collision>
            <origin xyz="0 0 0.06" />
            <geometry>
                <sphere radius="0.09" />
            </geometry>
        </collision>
        <collision>
            <origin xyz="0 0 -0.06" />
            <geometry>
                <sphere radius="0.09" />
            </geometry>
        </collision>
        <inertial>
            <mass value="0.1" />
            <origin xyz="0 0 0" rpy="0 0 0" />
            <inertia ixx="0.03" iyy="0.03" izz="0.03" ixy="0.0" ixz="0.0" iyz="0.0" />
        </inertial>
    </link>
    <!-- fixed joint between both sub-links -->
    <joint name="right_fr3_link2_sc_joint" type="fixed">
        <origin rpy="0 0 0" />
        <parent link="right_fr3_link2" />
        <child link="right_fr3_link2_sc" />
    </joint>
    <joint name="right_fr3_joint2" type="revolute">
        <origin rpy="-1.5707963267948966 0 0" xyz="0 0 0" />
        <parent link="right_fr3_link1" />
        <child link="right_fr3_link2" />
        <axis xyz="0 0 1" />
        <limit effort="87.0" lower="-1.7628" upper="1.7628" velocity="2.175" />
        <safety_controller k_position="100.0" k_velocity="40.0" soft_lower_limit="-1.7628" soft_upper_limit="1.7628" />
        <dynamics D="1" K="7000" damping="0.003" friction="0.0" mu_coulomb="0" mu_viscous="16" />
    </joint>
    <!-- sub-link defining detailed meshes for collision with environment -->
    <link name="right_fr3_link3">
        <visual>
            <geometry>
                <mesh filename="package://franka_description/meshes/visual/link3.dae" />
            </geometry>
        </visual>
        <collision>
            <geometry>
                <mesh filename="package://franka_description/meshes/collision/link3.stl" />
            </geometry>
        </collision>
        <inertial>
            <mass value="0.1" />
            <origin xyz="0 0 0" rpy="0 0 0" />
            <inertia ixx="0.03" iyy="0.03" izz="0.03" ixy="0.0" ixz="0.0" iyz="0.0" />
        </inertial>
    </link>
    <!-- sub-link defining coarse geometries of real robot's internal self-collision -->
    <link name="right_fr3_link3_sc">
        <collision>
            <origin rpy="0 0 0" xyz="0 0 -0.145" />
            <geometry>
                <cylinder length="0.15" radius="0.09" />
            </geometry>
        </collision>
        <collision>
            <origin xyz="0 0 -0.06999999999999999" />
            <geometry>
                <sphere radius="0.09" />
            </geometry>
        </collision>
        <collision>
            <origin xyz="0 0 -0.21999999999999997" />
            <geometry>
                <sphere radius="0.09" />
            </geometry>
        </collision>
        <inertial>
            <mass value="0.1" />
            <origin xyz="0 0 0" rpy="0 0 0" />
            <inertia ixx="0.03" iyy="0.03" izz="0.03" ixy="0.0" ixz="0.0" iyz="0.0" />
        </inertial>
    </link>
    <!-- fixed joint between both sub-links -->
    <joint name="right_fr3_link3_sc_joint" type="fixed">
        <origin rpy="0 0 0" />
        <parent link="right_fr3_link3" />
        <child link="right_fr3_link3_sc" />
    </joint>
    <joint name="right_fr3_joint3" type="revolute">
        <origin rpy="1.5707963267948966 0 0" xyz="0 -0.316 0" />
        <parent link="right_fr3_link2" />
        <child link="right_fr3_link3" />
        <axis xyz="0 0 1" />
        <limit effort="87.0" lower="-2.8973" upper="2.8973" velocity="2.175" />
        <safety_controller k_position="100.0" k_velocity="40.0" soft_lower_limit="-2.8973" soft_upper_limit="2.8973" />
        <dynamics D="1" K="7000" damping="0.003" friction="0.0" mu_coulomb="0" mu_viscous="16" />
    </joint>
    <!-- sub-link defining detailed meshes for collision with environment -->
    <link name="right_fr3_link4">
        <visual>
            <geometry>
                <mesh filename="package://franka_description/meshes/visual/link4.dae" />
            </geometry>
        </visual>
        <collision>
            <geometry>
                <mesh filename="package://franka_description/meshes/collision/link4.stl" />
            </geometry>
        </collision>
        <inertial>
            <mass value="0.1" />
            <origin xyz="0 0 0" rpy="0 0 0" />
            <inertia ixx="0.03" iyy="0.03" izz="0.03" ixy="0.0" ixz="0.0" iyz="0.0" />
        </inertial>
    </link>
    <!-- sub-link defining coarse geometries of real robot's internal self-collision -->
    <link name="right_fr3_link4_sc">
        <collision>
            <origin rpy="0 0 0" xyz="0 0 0" />
            <geometry>
                <cylinder length="0.12" radius="0.09" />
            </geometry>
        </collision>
        <collision>
            <origin xyz="0 0 0.06" />
            <geometry>
                <sphere radius="0.09" />
            </geometry>
        </collision>
        <collision>
            <origin xyz="0 0 -0.06" />
            <geometry>
                <sphere radius="0.09" />
            </geometry>
        </collision>
        <inertial>
            <mass value="0.1" />
            <origin xyz="0 0 0" rpy="0 0 0" />
            <inertia ixx="0.03" iyy="0.03" izz="0.03" ixy="0.0" ixz="0.0" iyz="0.0" />
        </inertial>
    </link>
    <!-- fixed joint between both sub-links -->
    <joint name="right_fr3_link4_sc_joint" type="fixed">
        <origin rpy="0 0 0" />
        <parent link="right_fr3_link4" />
        <child link="right_fr3_link4_sc" />
    </joint>
    <joint name="right_fr3_joint4" type="revolute">
        <origin rpy="1.5707963267948966 0 0" xyz="0.0825 0 0" />
        <parent link="right_fr3_link3" />
        <child link="right_fr3_link4" />
        <axis xyz="0 0 1" />
        <limit effort="87.0" lower="-3.0718" upper="-0.0698" velocity="2.175" />
        <safety_controller k_position="100.0" k_velocity="40.0" soft_lower_limit="-3.0718" soft_upper_limit="-0.0698" />
        <dynamics D="1" K="7000" damping="0.003" friction="0.0" mu_coulomb="0" mu_viscous="16" />
    </joint>
    <!-- sub-link defining detailed meshes for collision with environment -->
    <link name="right_fr3_link5">
        <visual>
            <geometry>
                <mesh filename="package://franka_description/meshes/visual/link5.dae" />
            </geometry>
        </visual>
        <collision>
            <geometry>
                <mesh filename="package://franka_description/meshes/collision/link5.stl" />
            </geometry>
        </collision>
        <inertial>
            <mass value="0.1" />
            <origin xyz="0 0 0" rpy="0 0 0" />
            <inertia ixx="0.03" iyy="0.03" izz="0.03" ixy="0.0" ixz="0.0" iyz="0.0" />
        </inertial>
    </link>
    <!-- sub-link defining coarse geometries of real robot's internal self-collision -->
    <link name="right_fr3_link5_sc">
        <collision>
            <origin rpy="0 0 0" xyz="0 0 -0.26" />
            <geometry>
                <cylinder length="0.1" radius="0.09" />
            </geometry>
        </collision>
        <collision>
            <origin xyz="0 0 -0.21000000000000002" />
            <geometry>
                <sphere radius="0.09" />
            </geometry>
        </collision>
        <collision>
            <origin xyz="0 0 -0.31" />
            <geometry>
                <sphere radius="0.09" />
            </geometry>
        </collision>
        <collision>
            <origin rpy="0 0 0.08" xyz="0 0.08 -0.13" />
            <geometry>
                <cylinder length="0.14" radius="0.055" />
            </geometry>
        </collision>
        <collision>
            <origin xyz="0 0.08 -0.06" />
            <geometry>
                <sphere radius="0.055" />
            </geometry>
        </collision>
        <collision>
            <origin xyz="0 0.08 -0.2" />
            <geometry>
                <sphere radius="0.055" />
            </geometry>
        </collision>
        <inertial>
            <mass value="0.1" />
            <origin xyz="0 0 0" rpy="0 0 0" />
            <inertia ixx="0.03" iyy="0.03" izz="0.03" ixy="0.0" ixz="0.0" iyz="0.0" />
        </inertial>
    </link>
    <!-- fixed joint between both sub-links -->
    <joint name="right_fr3_link5_sc_joint" type="fixed">
        <origin rpy="0 0 0" />
        <parent link="right_fr3_link5" />
        <child link="right_fr3_link5_sc" />
    </joint>
    <joint name="right_fr3_joint5" type="revolute">
        <origin rpy="-1.5707963267948966 0 0" xyz="-0.0825 0.384 0" />
        <parent link="right_fr3_link4" />
        <child link="right_fr3_link5" />
        <axis xyz="0 0 1" />
        <limit effort="12.0" lower="-2.8973" upper="2.8973" velocity="2.61" />
        <safety_controller k_position="100.0" k_velocity="40.0" soft_lower_limit="-2.8973" soft_upper_limit="2.8973" />
        <dynamics D="1" K="7000" damping="0.003" friction="0.0" mu_coulomb="0" mu_viscous="16" />
    </joint>
    <!-- sub-link defining detailed meshes for collision with environment -->
    <link name="right_fr3_link6">
        <visual>
            <geometry>
                <mesh filename="package://franka_description/meshes/visual/link6.dae" />
            </geometry>
        </visual>
        <collision>
            <geometry>
                <mesh filename="package://franka_description/meshes/collision/link6.stl" />
            </geometry>
        </collision>
        <inertial>
            <mass value="0.1" />
            <origin xyz="0 0 0" rpy="0 0 0" />
            <inertia ixx="0.03" iyy="0.03" izz="0.03" ixy="0.0" ixz="0.0" iyz="0.0" />
        </inertial>
    </link>
    <!-- sub-link defining coarse geometries of real robot's internal self-collision -->
    <link name="right_fr3_link6_sc">
        <collision>
            <origin rpy="0 0 0" xyz="0 0 -0.03" />
            <geometry>
                <cylinder length="0.08" radius="0.08" />
            </geometry>
        </collision>
        <collision>
            <origin xyz="0 0 0.010000000000000002" />
            <geometry>
                <sphere radius="0.08" />
            </geometry>
        </collision>
        <collision>
            <origin xyz="0 0 -0.07" />
            <geometry>
                <sphere radius="0.08" />
            </geometry>
        </collision>
        <inertial>
            <mass value="0.1" />
            <origin xyz="0 0 0" rpy="0 0 0" />
            <inertia ixx="0.03" iyy="0.03" izz="0.03" ixy="0.0" ixz="0.0" iyz="0.0" />
        </inertial>
    </link>
    <!-- fixed joint between both sub-links -->
    <joint name="right_fr3_link6_sc_joint" type="fixed">
        <origin rpy="0 0 0" />
        <parent link="right_fr3_link6" />
        <child link="right_fr3_link6_sc" />
    </joint>
    <joint name="right_fr3_joint6" type="revolute">
        <origin rpy="1.5707963267948966 0 0" xyz="0 0 0" />
        <parent link="right_fr3_link5" />
        <child link="right_fr3_link6" />
        <axis xyz="0 0 1" />
        <limit effort="12.0" lower="-0.0175" upper="3.7525" velocity="2.61" />
        <safety_controller k_position="100.0" k_velocity="40.0" soft_lower_limit="-0.0175" soft_upper_limit="3.7525" />
        <dynamics D="1" K="7000" damping="0.003" friction="0.0" mu_coulomb="0" mu_viscous="16" />
    </joint>
    <!-- sub-link defining detailed meshes for collision with environment -->
    <link name="right_fr3_link7">
        <visual>
            <geometry>
                <mesh filename="package://franka_description/meshes/visual/link7.dae" />
            </geometry>
        </visual>
        <collision>
            <geometry>
                <mesh filename="package://franka_description/meshes/collision/link7.stl" />
            </geometry>
        </collision>
        <inertial>
            <mass value="0.1" />
            <origin xyz="0 0 0" rpy="0 0 0" />
            <inertia ixx="0.03" iyy="0.03" izz="0.03" ixy="0.0" ixz="0.0" iyz="0.0" />
        </inertial>
    </link>
    <!-- sub-link defining coarse geometries of real robot's internal self-collision -->
    <link name="right_fr3_link7_sc">
        <collision>
            <origin rpy="0 0 0" xyz="0 0 0.01" />
            <geometry>
                <cylinder length="0.14" radius="0.07" />
            </geometry>
        </collision>
        <collision>
            <origin xyz="0 0 0.08" />
            <geometry>
                <sphere radius="0.07" />
            </geometry>
        </collision>
        <collision>
            <origin xyz="0 0 -0.060000000000000005" />
            <geometry>
                <sphere radius="0.07" />
            </geometry>
        </collision>
        <collision>
            <origin rpy="0 1.5707963267948966 0" xyz="0.06 0 0.082" />
            <geometry>
                <cylinder length="0.01" radius="0.06" />
            </geometry>
        </collision>
        <collision>
            <origin xyz="0.065 0 0.082" />
            <geometry>
                <sphere radius="0.06" />
            </geometry>
        </collision>
        <collision>
            <origin xyz="0.055 0 0.082" />
            <geometry>
                <sphere radius="0.06" />
            </geometry>
        </collision>
        <inertial>
            <mass value="0.1" />
            <origin xyz="0 0 0" rpy="0 0 0" />
            <inertia ixx="0.03" iyy="0.03" izz="0.03" ixy="0.0" ixz="0.0" iyz="0.0" />
        </inertial>
    </link>
    <!-- fixed joint between both sub-links -->
    <joint name="right_fr3_link7_sc_joint" type="fixed">
        <origin rpy="0 0 0.7853981633974483" />
        <parent link="right_fr3_link7" />
        <child link="right_fr3_link7_sc" />
    </joint>
    <joint name="right_fr3_joint7" type="revolute">
        <origin rpy="1.5707963267948966 0 0" xyz="0.088 0 0" />
        <parent link="right_fr3_link6" />
        <child link="right_fr3_link7" />
        <axis xyz="0 0 1" />
        <limit effort="12.0" lower="-2.8973" upper="2.8973" velocity="2.61" />
        <safety_controller k_position="100.0" k_velocity="40.0" soft_lower_limit="-2.8973" soft_upper_limit="2.8973" />
        <dynamics D="1" K="7000" damping="0.003" friction="0.0" mu_coulomb="0" mu_viscous="16" />
    </joint>
    <link name="right_fr3_link8" />
    <joint name="right_fr3_joint8" type="fixed">
        <origin rpy="0 0 0" xyz="0 0 0.107" />
        <parent link="right_fr3_link7" />
        <child link="right_fr3_link8" />
    </joint>
    <joint name="right_fr3_hand_joint" type="fixed">
        <parent link="right_fr3_link8" />
        <child link="right_fr3_hand" />
        <origin rpy="0 0 -0.7853981633974483" xyz="0 0 0" />
    </joint>
    <!-- sub-link defining detailed meshes for collision with environment -->
    <link name="right_fr3_hand">
        <visual>
            <geometry>
                <mesh filename="package://franka_description/meshes/visual/hand.dae" />
            </geometry>
        </visual>
        <collision>
            <geometry>
                <mesh filename="package://franka_description/meshes/collision/hand.stl" />
            </geometry>
        </collision>
        <inertial>
            <mass value="0.1" />
            <origin xyz="0 0 0" rpy="0 0 0" />
            <inertia ixx="0.03" iyy="0.03" izz="0.03" ixy="0.0" ixz="0.0" iyz="0.0" />
        </inertial>
    </link>
    <!-- sub-link defining coarse geometries of real robot's internal self-collision -->
    <link name="right_fr3_hand_sc">
        <collision>
            <origin rpy="1.5707963267948966 0 0" xyz="0 0 0.04" />
            <geometry>
                <cylinder length="0.1" radius="0.07" />
            </geometry>
        </collision>
        <collision>
            <origin xyz="0 0.05 0.04" />
            <geometry>
                <sphere radius="0.07" />
            </geometry>
        </collision>
        <collision>
            <origin xyz="0 -0.05 0.04" />
            <geometry>
                <sphere radius="0.07" />
            </geometry>
        </collision>
        <collision>
            <origin rpy="1.5707963267948966 0 0" xyz="0 0 0.1" />
            <geometry>
                <cylinder length="0.1" radius="0.05" />
            </geometry>
        </collision>
        <collision>
            <origin xyz="0 0.05 0.1" />
            <geometry>
                <sphere radius="0.05" />
            </geometry>
        </collision>
        <collision>
            <origin xyz="0 -0.05 0.1" />
            <geometry>
                <sphere radius="0.05" />
            </geometry>
        </collision>
        <inertial>
            <mass value="0.1" />
            <origin xyz="0 0 0" rpy="0 0 0" />
            <inertia ixx="0.03" iyy="0.03" izz="0.03" ixy="0.0" ixz="0.0" iyz="0.0" />
        </inertial>
    </link>
    <!-- fixed joint between both sub-links -->
    <joint name="right_fr3_hand_sc_joint" type="fixed">
        <origin rpy="0 0 0" />
        <parent link="right_fr3_hand" />
        <child link="right_fr3_hand_sc" />
    </joint>
    <!-- Define the hand_tcp frame -->
    <link name="right_fr3_hand_tcp" />
    <joint name="right_fr3_hand_tcp_joint" type="fixed">
        <origin rpy="0 0 0" xyz="0 0 0.1034" />
        <parent link="right_fr3_hand" />
        <child link="right_fr3_hand_tcp" />
    </joint>
    <link name="right_fr3_leftfinger">
        <visual>
            <geometry>
                <mesh filename="package://franka_description/meshes/visual/finger.dae" />
            </geometry>
        </visual>
        <!-- screw mount -->
        <collision>
            <origin rpy="0 0 0" xyz="0 18.5e-3 11e-3" />
            <geometry>
                <box size="22e-3 15e-3 20e-3" />
            </geometry>
        </collision>
        <!-- cartriage sledge -->
        <collision>
            <origin rpy="0 0 0" xyz="0 6.8e-3 2.2e-3" />
            <geometry>
                <box size="22e-3 8.8e-3 3.8e-3" />
            </geometry>
        </collision>
        <!-- diagonal finger -->
        <collision>
            <origin rpy="0.5235987755982988 0 0" xyz="0 15.9e-3 28.35e-3" />
            <geometry>
                <box size="17.5e-3 7e-3 23.5e-3" />
            </geometry>
        </collision>
        <!-- rubber tip with which to grasp -->
        <collision>
            <origin rpy="0 0 0" xyz="0 7.58e-3 45.25e-3" />
            <geometry>
                <box size="17.5e-3 15.2e-3 18.5e-3" />
            </geometry>
        </collision>
        <inertial>
            <mass value="0.1" />
            <origin xyz="0 0 0" rpy="0 0 0" />
            <inertia ixx="0.03" iyy="0.03" izz="0.03" ixy="0.0" ixz="0.0" iyz="0.0" />
        </inertial>
    </link>
    <link name="right_fr3_rightfinger">
        <visual>
            <origin rpy="0 0 3.141592653589793" xyz="0 0 0" />
            <geometry>
                <mesh filename="package://franka_description/meshes/visual/finger.dae" />
            </geometry>
        </visual>
        <!-- screw mount -->
        <collision>
            <origin rpy="0 0 0" xyz="0 -18.5e-3 11e-3" />
            <geometry>
                <box size="22e-3 15e-3 20e-3" />
            </geometry>
        </collision>
        <!-- cartriage sledge -->
        <collision>
            <origin rpy="0 0 0" xyz="0 -6.8e-3 2.2e-3" />
            <geometry>
                <box size="22e-3 8.8e-3 3.8e-3" />
            </geometry>
        </collision>
        <!-- diagonal finger -->
        <collision>
            <origin rpy="-0.5235987755982988 0 0" xyz="0 -15.9e-3 28.35e-3" />
            <geometry>
                <box size="17.5e-3 7e-3 23.5e-3" />
            </geometry>
        </collision>
        <!-- rubber tip with which to grasp -->
        <collision>
            <origin rpy="0 0 0" xyz="0 -7.58e-3 45.25e-3" />
            <geometry>
                <box size="17.5e-3 15.2e-3 18.5e-3" />
            </geometry>
        </collision>
        <inertial>
            <mass value="0.1" />
            <origin xyz="0 0 0" rpy="0 0 0" />
            <inertia ixx="0.03" iyy="0.03" izz="0.03" ixy="0.0" ixz="0.0" iyz="0.0" />
        </inertial>
    </link>
    <joint name="right_fr3_finger_joint1" type="prismatic">
        <parent link="right_fr3_hand" />
        <child link="right_fr3_leftfinger" />
        <origin rpy="0 0 0" xyz="0 0 0.0584" />
        <axis xyz="0 1 0" />
        <limit effort="100" lower="0.0" upper="0.04" velocity="0.2" />
        <dynamics damping="0.3" />
    </joint>
    <joint name="right_fr3_finger_joint2" type="prismatic">
        <parent link="right_fr3_hand" />
        <child link="right_fr3_rightfinger" />
        <origin rpy="0 0 0" xyz="0 0 0.0584" />
        <axis xyz="0 -1 0" />
        <limit effort="100" lower="0.0" upper="0.04" velocity="0.2" />
        <mimic joint="right_fr3_finger_joint1" />
        <dynamics damping="0.3" />
    </joint>
    <transmission name="trans_left_fr3_joint1">
        <type>transmission_interface/SimpleTransmission</type>
        <joint name="left_fr3_joint1">
            <hardwareInterface>hardware_interface/EffortJointInterface</hardwareInterface>
        </joint>
        <actuator name="left_fr3_joint1_motor">
            <hardwareInterface>hardware_interface/EffortJointInterface</hardwareInterface>
            <mechanicalReduction>1</mechanicalReduction>
        </actuator>
    </transmission>
    <transmission name="trans_left_fr3_joint2">
        <type>transmission_interface/SimpleTransmission</type>
        <joint name="left_fr3_joint2">
            <hardwareInterface>hardware_interface/EffortJointInterface</hardwareInterface>
        </joint>
        <actuator name="left_fr3_joint2_motor">
            <hardwareInterface>hardware_interface/EffortJointInterface</hardwareInterface>
            <mechanicalReduction>1</mechanicalReduction>
        </actuator>
    </transmission>
    <transmission name="trans_left_fr3_joint3">
        <type>transmission_interface/SimpleTransmission</type>
        <joint name="left_fr3_joint3">
            <hardwareInterface>hardware_interface/EffortJointInterface</hardwareInterface>
        </joint>
        <actuator name="left_fr3_joint3_motor">
            <hardwareInterface>hardware_interface/EffortJointInterface</hardwareInterface>
            <mechanicalReduction>1</mechanicalReduction>
        </actuator>
    </transmission>
    <transmission name="trans_left_fr3_joint4">
        <type>transmission_interface/SimpleTransmission</type>
        <joint name="left_fr3_joint4">
            <hardwareInterface>hardware_interface/EffortJointInterface</hardwareInterface>
        </joint>
        <actuator name="left_fr3_joint4_motor">
            <hardwareInterface>hardware_interface/EffortJointInterface</hardwareInterface>
            <mechanicalReduction>1</mechanicalReduction>
        </actuator>
    </transmission>
    <transmission name="trans_left_fr3_joint5">
        <type>transmission_interface/SimpleTransmission</type>
        <joint name="left_fr3_joint5">
            <hardwareInterface>hardware_interface/EffortJointInterface</hardwareInterface>
        </joint>
        <actuator name="left_fr3_joint5_motor">
            <hardwareInterface>hardware_interface/EffortJointInterface</hardwareInterface>
            <mechanicalReduction>1</mechanicalReduction>
        </actuator>
    </transmission>
    <transmission name="trans_left_fr3_joint6">
        <type>transmission_interface/SimpleTransmission</type>
        <joint name="left_fr3_joint6">
            <hardwareInterface>hardware_interface/EffortJointInterface</hardwareInterface>
        </joint>
        <actuator name="left_fr3_joint6_motor">
            <hardwareInterface>hardware_interface/EffortJointInterface</hardwareInterface>
            <mechanicalReduction>1</mechanicalReduction>
        </actuator>
    </transmission>
    <transmission name="trans_left_fr3_joint7">
        <type>transmission_interface/SimpleTransmission</type>
        <joint name="left_fr3_joint7">
            <hardwareInterface>hardware_interface/EffortJointInterface</hardwareInterface>
        </joint>
        <actuator name="left_fr3_joint7_motor">
            <hardwareInterface>hardware_interface/EffortJointInterface</hardwareInterface>
            <mechanicalReduction>1</mechanicalReduction>
        </actuator>
    </transmission>
    <transmission name="trans_left_fr3_finger_joint1">
        <type>transmission_interface/SimpleTransmission</type>
        <joint name="left_fr3_finger_joint1">
            <hardwareInterface>hardware_interface/EffortJointInterface</hardwareInterface>
        </joint>
        <actuator name="left_fr3_finger_joint1_motor">
            <hardwareInterface>hardware_interface/EffortJointInterface</hardwareInterface>
            <mechanicalReduction>1</mechanicalReduction>
        </actuator>
    </transmission>
    <transmission name="trans_left_fr3_finger_joint2">
        <type>transmission_interface/SimpleTransmission</type>
        <joint name="left_fr3_finger_joint2">
            <hardwareInterface>hardware_interface/EffortJointInterface</hardwareInterface>
        </joint>
        <actuator name="left_fr3_finger_joint2_motor">
            <hardwareInterface>hardware_interface/EffortJointInterface</hardwareInterface>
            <mechanicalReduction>1</mechanicalReduction>
        </actuator>
    </transmission>
    <transmission name="trans_right_fr3_joint1">
        <type>transmission_interface/SimpleTransmission</type>
        <joint name="right_fr3_joint1">
            <hardwareInterface>hardware_interface/EffortJointInterface</hardwareInterface>
        </joint>
        <actuator name="right_fr3_joint1_motor">
            <hardwareInterface>hardware_interface/EffortJointInterface</hardwareInterface>
            <mechanicalReduction>1</mechanicalReduction>
        </actuator>
    </transmission>
    <transmission name="trans_right_fr3_joint2">
        <type>transmission_interface/SimpleTransmission</type>
        <joint name="right_fr3_joint2">
            <hardwareInterface>hardware_interface/EffortJointInterface</hardwareInterface>
        </joint>
        <actuator name="right_fr3_joint2_motor">
            <hardwareInterface>hardware_interface/EffortJointInterface</hardwareInterface>
            <mechanicalReduction>1</mechanicalReduction>
        </actuator>
    </transmission>
    <transmission name="trans_right_fr3_joint3">
        <type>transmission_interface/SimpleTransmission</type>
        <joint name="right_fr3_joint3">
            <hardwareInterface>hardware_interface/EffortJointInterface</hardwareInterface>
        </joint>
        <actuator name="right_fr3_joint3_motor">
            <hardwareInterface>hardware_interface/EffortJointInterface</hardwareInterface>
            <mechanicalReduction>1</mechanicalReduction>
        </actuator>
    </transmission>
    <transmission name="trans_right_fr3_joint4">
        <type>transmission_interface/SimpleTransmission</type>
        <joint name="right_fr3_joint4">
            <hardwareInterface>hardware_interface/EffortJointInterface</hardwareInterface>
        </joint>
        <actuator name="right_fr3_joint4_motor">
            <hardwareInterface>hardware_interface/EffortJointInterface</hardwareInterface>
            <mechanicalReduction>1</mechanicalReduction>
        </actuator>
    </transmission>
    <transmission name="trans_right_fr3_joint5">
        <type>transmission_interface/SimpleTransmission</type>
        <joint name="right_fr3_joint5">
            <hardwareInterface>hardware_interface/EffortJointInterface</hardwareInterface>
        </joint>
        <actuator name="right_fr3_joint5_motor">
            <hardwareInterface>hardware_interface/EffortJointInterface</hardwareInterface>
            <mechanicalReduction>1</mechanicalReduction>
        </actuator>
    </transmission>
    <transmission name="trans_right_fr3_joint6">
        <type>transmission_interface/SimpleTransmission</type>
        <joint name="right_fr3_joint6">
            <hardwareInterface>hardware_interface/EffortJointInterface</hardwareInterface>
        </joint>
        <actuator name="right_fr3_joint6_motor">
            <hardwareInterface>hardware_interface/EffortJointInterface</hardwareInterface>
            <mechanicalReduction>1</mechanicalReduction>
        </actuator>
    </transmission>
    <transmission name="trans_right_fr3_joint7">
        <type>transmission_interface/SimpleTransmission</type>
        <joint name="right_fr3_joint7">
            <hardwareInterface>hardware_interface/EffortJointInterface</hardwareInterface>
        </joint>
        <actuator name="right_fr3_joint7_motor">
            <hardwareInterface>hardware_interface/EffortJointInterface</hardwareInterface>
            <mechanicalReduction>1</mechanicalReduction>
        </actuator>
    </transmission>
    <transmission name="trans_right_fr3_finger_joint1">
        <type>transmission_interface/SimpleTransmission</type>
        <joint name="right_fr3_finger_joint1">
            <hardwareInterface>hardware_interface/EffortJointInterface</hardwareInterface>
        </joint>
        <actuator name="right_fr3_finger_joint1_motor">
            <hardwareInterface>hardware_interface/EffortJointInterface</hardwareInterface>
            <mechanicalReduction>1</mechanicalReduction>
        </actuator>
    </transmission>
    <transmission name="trans_right_fr3_finger_joint2">
        <type>transmission_interface/SimpleTransmission</type>
        <joint name="right_fr3_finger_joint2">
            <hardwareInterface>hardware_interface/EffortJointInterface</hardwareInterface>
        </joint>
        <actuator name="right_fr3_finger_joint2_motor">
            <hardwareInterface>hardware_interface/EffortJointInterface</hardwareInterface>
            <mechanicalReduction>1</mechanicalReduction>
        </actuator>
    </transmission>
</robot>

